Workbook

Sheet README
A1: ATX Question Authoring Workbook (Fixed)
A3: Enter rows in the type sheets. IDs are generated from topic/component/subtopic_code.
A4: INDEX is derived automatically. Export to CSV with your Python exporter.
A6: Cloze list options separator: use | (pipe).
A7: Proforma lines_json: JSON list of {line_id,text,is_distractor}.

Sheet LOOKUPS
A1: Topics | C1: Components | E1: Priority | G1: Active | I1: Question types | K1: Topic | L1: TopicCode | N1: Component | O1: CompCode
A2: Ethics | C2: definitions | E2: core | G2: Y | I2: mcq_radio | K2: Ethics | L2: ETH | N2: definitions | O2: DEF
A3: Income tax & NIC | C3: requirements | E3: niche | G3: N | I3: cloze_ab | K3: Income tax & NIC | L3: ITNIC | N3: requirements | O3: REQ
A4: Capital gains | C4: exceptions | E4: edge | I4: cloze_list | K4: Capital gains | L4: CGT | N4: exceptions | O4: EXC
A5: Inheritance tax | C5: proformas | I5: proforma_drag | K5: Inheritance tax | L5: IHT | N5: proformas | O5: PF
A6: Loss reliefs | C6: calculations | K6: Loss reliefs | L6: LOSS | N6: calculations | O6: CALC
A7: Corporation tax | C7: filing_requirements | K7: Corporation tax | L7: CT | N7: filing_requirements | O7: FILE
A8: Groups | C8: penalties | K8: Groups | L8: GRP | N8: penalties | O8: PEN
A9: VAT | K9: VAT | L9: VAT

Sheet MCQ
A1: question_id | B1: topic | C1: component | D1: subtopic | E1: question_type | F1: difficulty | G1: priority | H1: active | I1: tags | J1: source_ref | K1: version | L1: subtopic_code | M1: id_prefix | N1: next_seq | O1: prompt | P1: option_a | Q1: option_b | R1: option_c | S1: option_d | T1: option_e | U1: correct_option | V1: explanation
A2: =IF(M2="","",M2&"_"&TEXT(N2,"000")) | E2: mcq_radio | M2: =IF(B2="","","MCQ"&"_"&IFERROR(VLOOKUP(B2,LOOKUPS!$K$2:$L$9,2,FALSE),"UNK")&"_"&IFERROR(VLOOKUP(C2,LOOKUPS!$N$2:$O$8,2,FALSE),"UNK")&"_"&UPPER(L2)) | N2: =IF(M2="","",COUNTIF($M$2:M2,M2))
A3: =IF(M3="","",M3&"_"&TEXT(N3,"000")) | E3: mcq_radio | M3: =IF(B3="","","MCQ"&"_"&IFERROR(VLOOKUP(B3,LOOKUPS!$K$2:$L$9,2,FALSE),"UNK")&"_"&IFERROR(VLOOKUP(C3,LOOKUPS!$N$2:$O$8,2,FALSE),"UNK")&"_"&UPPER(L3)) | N3: =IF(M3="","",COUNTIF($M$2:M3,M3))
A4: =IF(M4="","",M4&"_"&TEXT(N4,"000")) | E4: mcq_radio | M4: =IF(B4="","","MCQ"&"_"&IFERROR(VLOOKUP(B4,LOOKUPS!$K$2:$L$9,2,FALSE),"UNK")&"_"&IFERROR(VLOOKUP(C4,LOOKUPS!$N$2:$O$8,2,FALSE),"UNK")&"_"&UPPER(L4)) | N4: =IF(M4="","",COUNTIF($M$2:M4,M4))
A5: =IF(M5="","",M5&"_"&TEXT(N5,"000")) | E5: mcq_radio | M5: =IF(B5="","","MCQ"&"_"&IFERROR(VLOOKUP(B5,LOOKUPS!$K$2:$L$9,2,FALSE),"UNK")&"_"&IFERROR(VLOOKUP(C5,LOOKUPS!$N$2:$O$8,2,FALSE),"UNK")&"_"&UPPER(L5)) | N5: =IF(M5="","",COUNTIF($M$2:M5,M5))
A6: =IF(M6="","",M6&"_"&TEXT(N6,"000")) | E6: mcq_radio | M6: =IF(B6="","","MCQ"&"_"&IFERROR(VLOOKUP(B6,LOOKUPS!$K$2:$L$9,2,FALSE),"UNK")&"_"&IFERROR(VLOOKUP(C6,LOOKUPS!$N$2:$O$8,2,FALSE),"UNK")&"_"&UPPER(L6)) | N6: =IF(M6="","",COUNTIF($M$2:M6,M6))
A7: =IF(M7="","",M7&"_"&TEXT(N7,"000")) | E7: mcq_radio | M7: =IF(B7="","","MCQ"&"_"&IFERROR(VLOOKUP(B7,LOOKUPS!$K$2:$L$9,2,FALSE),"UNK")&"_"&IFERROR(VLOOKUP(C7,LOOKUPS!$N$2:$O$8,2,FALSE),"UNK")&"_"&UPPER(L7)) | N7: =IF(M7="","",COUNTIF($M$2:M7,M7))
A8: =IF(M8="","",M8&"_"&TEXT(N8,"000")) | E8: mcq_radio | M8: =IF(B8="","","MCQ"&"_"&IFERROR(VLOOKUP(B8,LOOKUPS!$K$2:$L$9,2,FALSE),"UNK")&"_"&IFERROR(VLOOKUP(C8,LOOKUPS!$N$2:$O$8,2,FALSE),"UNK")&"_"&UPPER(L8)) | N8: =IF(M8="","",COUNTIF($M$2:M8,M8))
A9: =IF(M9="","",M9&"_"&TEXT(N9,"000")) | E9: mcq_radio | M9: =IF(B9="","","MCQ"&"_"&IFERROR(VLOOKUP(B9,LOOKUPS!$K$2:$L$9,2,FALSE),"UNK")&"_"&IFERROR(VLOOKUP(C9,LOOKUPS!$N$2:$O$8,2,FALSE),"UNK")&"_"&UPPER(L9)) | N9: =IF(M9="","",COUNTIF($M$2:M9,M9))
A10: =IF(M10="","",M10&"_"&TEXT(N10,"000")) | E10: mcq_radio | M10: =IF(B10="","","MCQ"&"_"&IFERROR(VLOOKUP(B10,LOOKUPS!$K$2:$L$9,2,FALSE),"UNK")&"_"&IFERROR(VLOOKUP(C10,LOOKUPS!$N$2:$O$8,2,FALSE),"UNK")&"_"&UPPER(L10)) | N10: =IF(M10="","",COUNTIF($M$2:M10,M10))
A11: =IF(M11="","",M11&"_"&TEXT(N11,"000")) | E11: mcq_radio | M11: =IF(B11="","","MCQ"&"_"&IFERROR(VLOOKUP(B11,LOOKUPS!$K$2:$L$9,2,FALSE),"UNK")&"_"&IFERROR(VLOOKUP(C11,LOOKUPS!$N$2:$O$8,2,FALSE),"UNK")&"_"&UPPER(L11)) | N11: =IF(M11="","",COUNTIF($M$2:M11,M11))
A12: =IF(M12="","",M12&"_"&TEXT(N12,"000")) | E12: mcq_radio | M12: =IF(B12="","","MCQ"&"_"&IFERROR(VLOOKUP(B12,LOOKUPS!$K$2:$L$9,2,FALSE),"UNK")&"_"&IFERROR(VLOOKUP(C12,LOOKUPS!$N$2:$O$8,2,FALSE),"UNK")&"_"&UPPER(L12)) | N12: =IF(M12="","",COUNTIF($M$2:M12,M12))
A13: =IF(M13="","",M13&"_"&TEXT(N13,"000")) | E13: mcq_radio | M13: =IF(B13="","","MCQ"&"_"&IFERROR(VLOOKUP(B13,LOOKUPS!$K$2:$L$9,2,FALSE),"UNK")&"_"&IFERROR(VLOOKUP(C13,LOOKUPS!$N$2:$O$8,2,FALSE),"UNK")&"_"&UPPER(L13)) | N13: =IF(M13="","",COUNTIF($M$2:M13,M13))
... A144: =IF(M144="","",M144&"_"&TEXT(N144,"000")) | E144: mcq_radio | M144: =IF(B144="","","MCQ"&"_"&IFERROR(VLOOKUP(B144,LOOKUPS!$K$2:$L$9,2,FALSE),"UNK")&"_"&IFERROR(VLOOKUP(C144,LOOKUPS!$N$2:$O$8,2,FALSE),"UNK")&"_"&UPPER(L144)) | N144: =IF(M144="","",COUNTIF($M$2:M144,M144))

Sheet CLOZE_AB
A1: question_id | B1: topic | C1: component | D1: subtopic | E1: question_type | F1: difficulty | G1: priority | H1: active | I1: tags | J1: source_ref | K1: version | L1: subtopic_code | M1: id_prefix | N1: next_seq | O1: prompt_template | P1: gap_count | Q1: choice_a | R1: choice_b | S1: gap1_correct | T1: gap1_allow_repeat | U1: gap2_correct | V1: gap2_allow_repeat | W1: gap3_correct | X1: gap3_allow_repeat | Y1: gap4_correct | Z1: gap4_allow_repeat | AA1: gap5_correct | AB1: gap5_allow_repeat | AC1: explanation
A2: =IF(M2="","",M2&"_"&TEXT(N2,"000")) | E2: cloze_ab | M2: =IF(B2="","","AB"&"_"&IFERROR(VLOOKUP(B2,LOOKUPS!$K$2:$L$9,2,FALSE),"UNK")&"_"&IFERROR(VLOOKUP(C2,LOOKUPS!$N$2:$O$8,2,FALSE),"UNK")&"_"&UPPER(L2)) | N2: =IF(M2="","",COUNTIF($M$2:M2,M2))
A3: =IF(M3="","",M3&"_"&TEXT(N3,"000")) | E3: cloze_ab | M3: =IF(B3="","","AB"&"_"&IFERROR(VLOOKUP(B3,LOOKUPS!$K$2:$L$9,2,FALSE),"UNK")&"_"&IFERROR(VLOOKUP(C3,LOOKUPS!$N$2:$O$8,2,FALSE),"UNK")&"_"&UPPER(L3)) | N3: =IF(M3="","",COUNTIF($M$2:M3,M3))
A4: =IF(M4="","",M4&"_"&TEXT(N4,"000")) | E4: cloze_ab | M4: =IF(B4="","","AB"&"_"&IFERROR(VLOOKUP(B4,LOOKUPS!$K$2:$L$9,2,FALSE),"UNK")&"_"&IFERROR(VLOOKUP(C4,LOOKUPS!$N$2:$O$8,2,FALSE),"UNK")&"_"&UPPER(L4)) | N4: =IF(M4="","",COUNTIF($M$2:M4,M4))
A5: =IF(M5="","",M5&"_"&TEXT(N5,"000")) | E5: cloze_ab | M5: =IF(B5="","","AB"&"_"&IFERROR(VLOOKUP(B5,LOOKUPS!$K$2:$L$9,2,FALSE),"UNK")&"_"&IFERROR(VLOOKUP(C5,LOOKUPS!$N$2:$O$8,2,FALSE),"UNK")&"_"&UPPER(L5)) | N5: =IF(M5="","",COUNTIF($M$2:M5,M5))
A6: =IF(M6="","",M6&"_"&TEXT(N6,"000")) | E6: cloze_ab | M6: =IF(B6="","","AB"&"_"&IFERROR(VLOOKUP(B6,LOOKUPS!$K$2:$L$9,2,FALSE),"UNK")&"_"&IFERROR(VLOOKUP(C6,LOOKUPS!$N$2:$O$8,2,FALSE),"UNK")&"_"&UPPER(L6)) | N6: =IF(M6="","",COUNTIF($M$2:M6,M6))
A7: =IF(M7="","",M7&"_"&TEXT(N7,"000")) | E7: cloze_ab | M7: =IF(B7="","","AB"&"_"&IFERROR(VLOOKUP(B7,LOOKUPS!$K$2:$L$9,2,FALSE),"UNK")&"_"&IFERROR(VLOOKUP(C7,LOOKUPS!$N$2:$O$8,2,FALSE),"UNK")&"_"&UPPER(L7)) | N7: =IF(M7="","",COUNTIF($M$2:M7,M7))
A8: =IF(M8="","",M8&"_"&TEXT(N8,"000")) | E8: cloze_ab | M8: =IF(B8="","","AB"&"_"&IFERROR(VLOOKUP(B8,LOOKUPS!$K$2:$L$9,2,FALSE),"UNK")&"_"&IFERROR(VLOOKUP(C8,LOOKUPS!$N$2:$O$8,2,FALSE),"UNK")&"_"&UPPER(L8)) | N8: =IF(M8="","",COUNTIF($M$2:M8,M8))
A9: =IF(M9="","",M9&"_"&TEXT(N9,"000")) | E9: cloze_ab | M9: =IF(B9="","","AB"&"_"&IFERROR(VLOOKUP(B9,LOOKUPS!$K$2:$L$9,2,FALSE),"UNK")&"_"&IFERROR(VLOOKUP(C9,LOOKUPS!$N$2:$O$8,2,FALSE),"UNK")&"_"&UPPER(L9)) | N9: =IF(M9="","",COUNTIF($M$2:M9,M9))
A10: =IF(M10="","",M10&"_"&TEXT(N10,"000")) | E10: cloze_ab | M10: =IF(B10="","","AB"&"_"&IFERROR(VLOOKUP(B10,LOOKUPS!$K$2:$L$9,2,FALSE),"UNK")&"_"&IFERROR(VLOOKUP(C10,LOOKUPS!$N$2:$O$8,2,FALSE),"UNK")&"_"&UPPER(L10)) | N10: =IF(M10="","",COUNTIF($M$2:M10,M10))
A11: =IF(M11="","",M11&"_"&TEXT(N11,"000")) | E11: cloze_ab | M11: =IF(B11="","","AB"&"_"&IFERROR(VLOOKUP(B11,LOOKUPS!$K$2:$L$9,2,FALSE),"UNK")&"_"&IFERROR(VLOOKUP(C11,LOOKUPS!$N$2:$O$8,2,FALSE),"UNK")&"_"&UPPER(L11)) | N11: =IF(M11="","",COUNTIF($M$2:M11,M11))
A12: =IF(M12="","",M12&"_"&TEXT(N12,"000")) | E12: cloze_ab | M12: =IF(B12="","","AB"&"_"&IFERROR(VLOOKUP(B12,LOOKUPS!$K$2:$L$9,2,FALSE),"UNK")&"_"&IFERROR(VLOOKUP(C12,LOOKUPS!$N$2:$O$8,2,FALSE),"UNK")&"_"&UPPER(L12)) | N12: =IF(M12="","",COUNTIF($M$2:M12,M12))
A13: =IF(M13="","",M13&"_"&TEXT(N13,"000")) | E13: cloze_ab | M13: =IF(B13="","","AB"&"_"&IFERROR(VLOOKUP(B13,LOOKUPS!$K$2:$L$9,2,FALSE),"UNK")&"_"&IFERROR(VLOOKUP(C13,LOOKUPS!$N$2:$O$8,2,FALSE),"UNK")&"_"&UPPER(L13)) | N13: =IF(M13="","",COUNTIF($M$2:M13,M13))
... A169: =IF(M169="","",M169&"_"&TEXT(N169,"000")) | E169: cloze_ab | M169: =IF(B169="","","AB"&"_"&IFERROR(VLOOKUP(B169,LOOKUPS!$K$2:$L$9,2,FALSE),"UNK")&"_"&IFERROR(VLOOKUP(C169,LOOKUPS!$N$2:$O$8,2,FALSE),"UNK")&"_"&UPPER(L169)) | N169: =IF(M169="","",COUNTIF($M$2:M169,M169))

Sheet CLOZE_LIST
A1: question_id | B1: topic | C1: component | D1: subtopic | E1: question_type | F1: difficulty | G1: priority | H1: active | I1: tags | J1: source_ref | K1: version | L1: subtopic_code | M1: id_prefix | N1: next_seq | O1: prompt_template | P1: gap_count | Q1: gap1_options | R1: gap1_correct | S1: gap1_allow_repeat | T1: gap2_options | U1: gap2_correct | V1: gap2_allow_repeat | W1: gap3_options | X1: gap3_correct | Y1: gap3_allow_repeat | Z1: gap4_options | AA1: gap4_correct | AB1: gap4_allow_repeat | AC1: gap5_options | AD1: gap5_correct | AE1: gap5_allow_repeat | AF1: enforce_unique_across_gaps | AG1: explanation
A2: =IF(M2="","",M2&"_"&TEXT(N2,"000")) | E2: cloze_list | M2: =IF(B2="","","LIST"&"_"&IFERROR(VLOOKUP(B2,LOOKUPS!$K$2:$L$9,2,FALSE),"UNK")&"_"&IFERROR(VLOOKUP(C2,LOOKUPS!$N$2:$O$8,2,FALSE),"UNK")&"_"&UPPER(L2)) | N2: =IF(M2="","",COUNTIF($M$2:M2,M2))
A3: =IF(M3="","",M3&"_"&TEXT(N3,"000")) | E3: cloze_list | M3: =IF(B3="","","LIST"&"_"&IFERROR(VLOOKUP(B3,LOOKUPS!$K$2:$L$9,2,FALSE),"UNK")&"_"&IFERROR(VLOOKUP(C3,LOOKUPS!$N$2:$O$8,2,FALSE),"UNK")&"_"&UPPER(L3)) | N3: =IF(M3="","",COUNTIF($M$2:M3,M3))
A4: =IF(M4="","",M4&"_"&TEXT(N4,"000")) | E4: cloze_list | M4: =IF(B4="","","LIST"&"_"&IFERROR(VLOOKUP(B4,LOOKUPS!$K$2:$L$9,2,FALSE),"UNK")&"_"&IFERROR(VLOOKUP(C4,LOOKUPS!$N$2:$O$8,2,FALSE),"UNK")&"_"&UPPER(L4)) | N4: =IF(M4="","",COUNTIF($M$2:M4,M4))
A5: =IF(M5="","",M5&"_"&TEXT(N5,"000")) | E5: cloze_list | M5: =IF(B5="","","LIST"&"_"&IFERROR(VLOOKUP(B5,LOOKUPS!$K$2:$L$9,2,FALSE),"UNK")&"_"&IFERROR(VLOOKUP(C5,LOOKUPS!$N$2:$O$8,2,FALSE),"UNK")&"_"&UPPER(L5)) | N5: =IF(M5="","",COUNTIF($M$2:M5,M5))
A6: =IF(M6="","",M6&"_"&TEXT(N6,"000")) | E6: cloze_list | M6: =IF(B6="","","LIST"&"_"&IFERROR(VLOOKUP(B6,LOOKUPS!$K$2:$L$9,2,FALSE),"UNK")&"_"&IFERROR(VLOOKUP(C6,LOOKUPS!$N$2:$O$8,2,FALSE),"UNK")&"_"&UPPER(L6)) | N6: =IF(M6="","",COUNTIF($M$2:M6,M6))
A7: =IF(M7="","",M7&"_"&TEXT(N7,"000")) | E7: cloze_list | M7: =IF(B7="","","LIST"&"_"&IFERROR(VLOOKUP(B7,LOOKUPS!$K$2:$L$9,2,FALSE),"UNK")&"_"&IFERROR(VLOOKUP(C7,LOOKUPS!$N$2:$O$8,2,FALSE),"UNK")&"_"&UPPER(L7)) | N7: =IF(M7="","",COUNTIF($M$2:M7,M7))
A8: =IF(M8="","",M8&"_"&TEXT(N8,"000")) | E8: cloze_list | M8: =IF(B8="","","LIST"&"_"&IFERROR(VLOOKUP(B8,LOOKUPS!$K$2:$L$9,2,FALSE),"UNK")&"_"&IFERROR(VLOOKUP(C8,LOOKUPS!$N$2:$O$8,2,FALSE),"UNK")&"_"&UPPER(L8)) | N8: =IF(M8="","",COUNTIF($M$2:M8,M8))
A9: =IF(M9="","",M9&"_"&TEXT(N9,"000")) | E9: cloze_list | M9: =IF(B9="","","LIST"&"_"&IFERROR(VLOOKUP(B9,LOOKUPS!$K$2:$L$9,2,FALSE),"UNK")&"_"&IFERROR(VLOOKUP(C9,LOOKUPS!$N$2:$O$8,2,FALSE),"UNK")&"_"&UPPER(L9)) | N9: =IF(M9="","",COUNTIF($M$2:M9,M9))
A10: =IF(M10="","",M10&"_"&TEXT(N10,"000")) | E10: cloze_list | M10: =IF(B10="","","LIST"&"_"&IFERROR(VLOOKUP(B10,LOOKUPS!$K$2:$L$9,2,FALSE),"UNK")&"_"&IFERROR(VLOOKUP(C10,LOOKUPS!$N$2:$O$8,2,FALSE),"UNK")&"_"&UPPER(L10)) | N10: =IF(M10="","",COUNTIF($M$2:M10,M10))
A11: =IF(M11="","",M11&"_"&TEXT(N11,"000")) | E11: cloze_list | M11: =IF(B11="","","LIST"&"_"&IFERROR(VLOOKUP(B11,LOOKUPS!$K$2:$L$9,2,FALSE),"UNK")&"_"&IFERROR(VLOOKUP(C11,LOOKUPS!$N$2:$O$8,2,FALSE),"UNK")&"_"&UPPER(L11)) | N11: =IF(M11="","",COUNTIF($M$2:M11,M11))
A12: =IF(M12="","",M12&"_"&TEXT(N12,"000")) | E12: cloze_list | M12: =IF(B12="","","LIST"&"_"&IFERROR(VLOOKUP(B12,LOOKUPS!$K$2:$L$9,2,FALSE),"UNK")&"_"&IFERROR(VLOOKUP(C12,LOOKUPS!$N$2:$O$8,2,FALSE),"UNK")&"_"&UPPER(L12)) | N12: =IF(M12="","",COUNTIF($M$2:M12,M12))
A13: =IF(M13="","",M13&"_"&TEXT(N13,"000")) | E13: cloze_list | M13: =IF(B13="","","LIST"&"_"&IFERROR(VLOOKUP(B13,LOOKUPS!$K$2:$L$9,2,FALSE),"UNK")&"_"&IFERROR(VLOOKUP(C13,LOOKUPS!$N$2:$O$8,2,FALSE),"UNK")&"_"&UPPER(L13)) | N13: =IF(M13="","",COUNTIF($M$2:M13,M13))
... A200: =IF(M200="","",M200&"_"&TEXT(N200,"000")) | E200: cloze_list | M200: =IF(B200="","","LIST"&"_"&IFERROR(VLOOKUP(B200,LOOKUPS!$K$2:$L$9,2,FALSE),"UNK")&"_"&IFERROR(VLOOKUP(C200,LOOKUPS!$N$2:$O$8,2,FALSE),"UNK")&"_"&UPPER(L200)) | N200: =IF(M200="","",COUNTIF($M$2:M200,M200))

Sheet PROFORMA
A1: question_id | B1: topic | C1: component | D1: subtopic | E1: question_type | F1: difficulty | G1: priority | H1: active | I1: tags | J1: source_ref | K1: version | L1: subtopic_code | M1: id_prefix | N1: next_seq | O1: title | P1: instructions | Q1: slot_count | R1: slot1_label | S1: slot1_correct_line_id | T1: slot2_label | U1: slot2_correct_line_id | V1: slot3_label | W1: slot3_correct_line_id | X1: slot4_label | Y1: slot4_correct_line_id | Z1: slot5_label | AA1: slot5_correct_line_id | AB1: lines_json | AC1: explanation
A2: =IF(M2="","",M2&"_"&TEXT(N2,"000")) | E2: proforma_drag | M2: =IF(B2="","","PF"&"_"&IFERROR(VLOOKUP(B2,LOOKUPS!$K$2:$L$9,2,FALSE),"UNK")&"_"&IFERROR(VLOOKUP(C2,LOOKUPS!$N$2:$O$8,2,FALSE),"UNK")&"_"&UPPER(L2)) | N2: =IF(M2="","",COUNTIF($M$2:M2,M2))
A3: =IF(M3="","",M3&"_"&TEXT(N3,"000")) | E3: proforma_drag | M3: =IF(B3="","","PF"&"_"&IFERROR(VLOOKUP(B3,LOOKUPS!$K$2:$L$9,2,FALSE),"UNK")&"_"&IFERROR(VLOOKUP(C3,LOOKUPS!$N$2:$O$8,2,FALSE),"UNK")&"_"&UPPER(L3)) | N3: =IF(M3="","",COUNTIF($M$2:M3,M3))
A4: =IF(M4="","",M4&"_"&TEXT(N4,"000")) | E4: proforma_drag | M4: =IF(B4="","","PF"&"_"&IFERROR(VLOOKUP(B4,LOOKUPS!$K$2:$L$9,2,FALSE),"UNK")&"_"&IFERROR(VLOOKUP(C4,LOOKUPS!$N$2:$O$8,2,FALSE),"UNK")&"_"&UPPER(L4)) | N4: =IF(M4="","",COUNTIF($M$2:M4,M4))
A5: =IF(M5="","",M5&"_"&TEXT(N5,"000")) | E5: proforma_drag | M5: =IF(B5="","","PF"&"_"&IFERROR(VLOOKUP(B5,LOOKUPS!$K$2:$L$9,2,FALSE),"UNK")&"_"&IFERROR(VLOOKUP(C5,LOOKUPS!$N$2:$O$8,2,FALSE),"UNK")&"_"&UPPER(L5)) | N5: =IF(M5="","",COUNTIF($M$2:M5,M5))
A6: =IF(M6="","",M6&"_"&TEXT(N6,"000")) | E6: proforma_drag | M6: =IF(B6="","","PF"&"_"&IFERROR(VLOOKUP(B6,LOOKUPS!$K$2:$L$9,2,FALSE),"UNK")&"_"&IFERROR(VLOOKUP(C6,LOOKUPS!$N$2:$O$8,2,FALSE),"UNK")&"_"&UPPER(L6)) | N6: =IF(M6="","",COUNTIF($M$2:M6,M6))
A7: =IF(M7="","",M7&"_"&TEXT(N7,"000")) | E7: proforma_drag | M7: =IF(B7="","","PF"&"_"&IFERROR(VLOOKUP(B7,LOOKUPS!$K$2:$L$9,2,FALSE),"UNK")&"_"&IFERROR(VLOOKUP(C7,LOOKUPS!$N$2:$O$8,2,FALSE),"UNK")&"_"&UPPER(L7)) | N7: =IF(M7="","",COUNTIF($M$2:M7,M7))
A8: =IF(M8="","",M8&"_"&TEXT(N8,"000")) | E8: proforma_drag | M8: =IF(B8="","","PF"&"_"&IFERROR(VLOOKUP(B8,LOOKUPS!$K$2:$L$9,2,FALSE),"UNK")&"_"&IFERROR(VLOOKUP(C8,LOOKUPS!$N$2:$O$8,2,FALSE),"UNK")&"_"&UPPER(L8)) | N8: =IF(M8="","",COUNTIF($M$2:M8,M8))
A9: =IF(M9="","",M9&"_"&TEXT(N9,"000")) | E9: proforma_drag | M9: =IF(B9="","","PF"&"_"&IFERROR(VLOOKUP(B9,LOOKUPS!$K$2:$L$9,2,FALSE),"UNK")&"_"&IFERROR(VLOOKUP(C9,LOOKUPS!$N$2:$O$8,2,FALSE),"UNK")&"_"&UPPER(L9)) | N9: =IF(M9="","",COUNTIF($M$2:M9,M9))
A10: =IF(M10="","",M10&"_"&TEXT(N10,"000")) | E10: proforma_drag | M10: =IF(B10="","","PF"&"_"&IFERROR(VLOOKUP(B10,LOOKUPS!$K$2:$L$9,2,FALSE),"UNK")&"_"&IFERROR(VLOOKUP(C10,LOOKUPS!$N$2:$O$8,2,FALSE),"UNK")&"_"&UPPER(L10)) | N10: =IF(M10="","",COUNTIF($M$2:M10,M10))
A11: =IF(M11="","",M11&"_"&TEXT(N11,"000")) | E11: proforma_drag | M11: =IF(B11="","","PF"&"_"&IFERROR(VLOOKUP(B11,LOOKUPS!$K$2:$L$9,2,FALSE),"UNK")&"_"&IFERROR(VLOOKUP(C11,LOOKUPS!$N$2:$O$8,2,FALSE),"UNK")&"_"&UPPER(L11)) | N11: =IF(M11="","",COUNTIF($M$2:M11,M11))
A12: =IF(M12="","",M12&"_"&TEXT(N12,"000")) | E12: proforma_drag | M12: =IF(B12="","","PF"&"_"&IFERROR(VLOOKUP(B12,LOOKUPS!$K$2:$L$9,2,FALSE),"UNK")&"_"&IFERROR(VLOOKUP(C12,LOOKUPS!$N$2:$O$8,2,FALSE),"UNK")&"_"&UPPER(L12)) | N12: =IF(M12="","",COUNTIF($M$2:M12,M12))
A13: =IF(M13="","",M13&"_"&TEXT(N13,"000")) | E13: proforma_drag | M13: =IF(B13="","","PF"&"_"&IFERROR(VLOOKUP(B13,LOOKUPS!$K$2:$L$9,2,FALSE),"UNK")&"_"&IFERROR(VLOOKUP(C13,LOOKUPS!$N$2:$O$8,2,FALSE),"UNK")&"_"&UPPER(L13)) | N13: =IF(M13="","",COUNTIF($M$2:M13,M13))
... A200: =IF(M200="","",M200&"_"&TEXT(N200,"000")) | E200: proforma_drag | M200: =IF(B200="","","PF"&"_"&IFERROR(VLOOKUP(B200,LOOKUPS!$K$2:$L$9,2,FALSE),"UNK")&"_"&IFERROR(VLOOKUP(C200,LOOKUPS!$N$2:$O$8,2,FALSE),"UNK")&"_"&UPPER(L200)) | N200: =IF(M200="","",COUNTIF($M$2:M200,M200))

Sheet INDEX
A1: question_id | B1: topic | C1: component | D1: subtopic | E1: question_type | F1: difficulty | G1: priority | H1: active | I1: tags | J1: source_ref | K1: version | L1: mcq_n | M1: ab_n | N1: list_n | O1: pf_n
A2: =IF(ROW()-1<=0,"",IF(ROW()-1<=$L$2,IFERROR(INDEX(MCQ!$A:$K,ROW()-1+1,1),""),IF(ROW()-1<=$L$2+$M$2,IFERROR(INDEX(CLOZE_AB!$A:$K,ROW()-1-$L$2+1,1),""),IF(ROW()-1<=$L$2+$M$2+$N$2,IFERROR(INDEX(CLOZE_LIST!$A:$K,ROW()-1-$L$2-$M$2+1,1),""),IF(ROW()-1<=$L$2+$M$2+$N$2+$O$2,IFERROR(INDEX(PROFORMA!$A:$K,ROW()-1-$L$2-$M$2-$N$2+1,1),""),""))))) | B2: =IF(ROW()-1<=0,"",IF(ROW()-1<=$L$2,IFERROR(INDEX(MCQ!$A:$K,ROW()-1+1,2),""),IF(ROW()-1<=$L$2+$M$2,IFERROR(INDEX(CLOZE_AB!$A:$K,ROW()-1-$L$2+1,2),""),IF(ROW()-1<=$L$2+$M$2+$N$2,IFERROR(INDEX(CLOZE_LIST!$A:$K,ROW()-1-$L$2-$M$2+1,2),""),IF(ROW()-1<=$L$2+$M$2+$N$2+$O$2,IFERROR(INDEX(PROFORMA!$A:$K,ROW()-1-$L$2-$M$2-$N$2+1,2),""),""))))) -> 0 | C2: =IF(ROW()-1<=0,"",IF(ROW()-1<=$L$2,IFERROR(INDEX(MCQ!$A:$K,ROW()-1+1,3),""),IF(ROW()-1<=$L$2+$M$2,IFERROR(INDEX(CLOZE_AB!$A:$K,ROW()-1-$L$2+1,3),""),IF(ROW()-1<=$L$2+$M$2+$N$2,IFERROR(INDEX(CLOZE_LIST!$A:$K,ROW()-1-$L$2-$M$2+1,3),""),IF(ROW()-1<=$L$2+$M$2+$N$2+$O$2,IFERROR(INDEX(PROFORMA!$A:$K,ROW()-1-$L$2-$M$2-$N$2+1,3),""),""))))) -> 0 | D2: =IF(ROW()-1<=0,"",IF(ROW()-1<=$L$2,IFERROR(INDEX(MCQ!$A:$K,ROW()-1+1,4),""),IF(ROW()-1<=$L$2+$M$2,IFERROR(INDEX(CLOZE_AB!$A:$K,ROW()-1-$L$2+1,4),""),IF(ROW()-1<=$L$2+$M$2+$N$2,IFERROR(INDEX(CLOZE_LIST!$A:$K,ROW()-1-$L$2-$M$2+1,4),""),IF(ROW()-1<=$L$2+$M$2+$N$2+$O$2,IFERROR(INDEX(PROFORMA!$A:$K,ROW()-1-$L$2-$M$2-$N$2+1,4),""),""))))) -> 0 | E2: =IF(ROW()-1<=0,"",IF(ROW()-1<=$L$2,IFERROR(INDEX(MCQ!$A:$K,ROW()-1+1,5),""),IF(ROW()-1<=$L$2+$M$2,IFERROR(INDEX(CLOZE_AB!$A:$K,ROW()-1-$L$2+1,5),""),IF(ROW()-1<=$L$2+$M$2+$N$2,IFERROR(INDEX(CLOZE_LIST!$A:$K,ROW()-1-$L$2-$M$2+1,5),""),IF(ROW()-1<=$L$2+$M$2+$N$2+$O$2,IFERROR(INDEX(PROFORMA!$A:$K,ROW()-1-$L$2-$M$2-$N$2+1,5),""),""))))) -> mcq_radio | F2: =IF(ROW()-1<=0,"",IF(ROW()-1<=$L$2,IFERROR(INDEX(MCQ!$A:$K,ROW()-1+1,6),""),IF(ROW()-1<=$L$2+$M$2,IFERROR(INDEX(CLOZE_AB!$A:$K,ROW()-1-$L$2+1,6),""),IF(ROW()-1<=$L$2+$M$2+$N$2,IFERROR(INDEX(CLOZE_LIST!$A:$K,ROW()-1-$L$2-$M$2+1,6),""),IF(ROW()-1<=$L$2+$M$2+$N$2+$O$2,IFERROR(INDEX(PROFORMA!$A:$K,ROW()-1-$L$2-$M$2-$N$2+1,6),""),""))))) -> 0 | G2: =IF(ROW()-1<=0,"",IF(ROW()-1<=$L$2,IFERROR(INDEX(MCQ!$A:$K,ROW()-1+1,7),""),IF(ROW()-1<=$L$2+$M$2,IFERROR(INDEX(CLOZE_AB!$A:$K,ROW()-1-$L$2+1,7),""),IF(ROW()-1<=$L$2+$M$2+$N$2,IFERROR(INDEX(CLOZE_LIST!$A:$K,ROW()-1-$L$2-$M$2+1,7),""),IF(ROW()-1<=$L$2+$M$2+$N$2+$O$2,IFERROR(INDEX(PROFORMA!$A:$K,ROW()-1-$L$2-$M$2-$N$2+1,7),""),""))))) -> 0 | H2: =IF(ROW()-1<=0,"",IF(ROW()-1<=$L$2,IFERROR(INDEX(MCQ!$A:$K,ROW()-1+1,8),""),IF(ROW()-1<=$L$2+$M$2,IFERROR(INDEX(CLOZE_AB!$A:$K,ROW()-1-$L$2+1,8),""),IF(ROW()-1<=$L$2+$M$2+$N$2,IFERROR(INDEX(CLOZE_LIST!$A:$K,ROW()-1-$L$2-$M$2+1,8),""),IF(ROW()-1<=$L$2+$M$2+$N$2+$O$2,IFERROR(INDEX(PROFORMA!$A:$K,ROW()-1-$L$2-$M$2-$N$2+1,8),""),""))))) -> 0 | I2: =IF(ROW()-1<=0,"",IF(ROW()-1<=$L$2,IFERROR(INDEX(MCQ!$A:$K,ROW()-1+1,9),""),IF(ROW()-1<=$L$2+$M$2,IFERROR(INDEX(CLOZE_AB!$A:$K,ROW()-1-$L$2+1,9),""),IF(ROW()-1<=$L$2+$M$2+$N$2,IFERROR(INDEX(CLOZE_LIST!$A:$K,ROW()-1-$L$2-$M$2+1,9),""),IF(ROW()-1<=$L$2+$M$2+$N$2+$O$2,IFERROR(INDEX(PROFORMA!$A:$K,ROW()-1-$L$2-$M$2-$N$2+1,9),""),""))))) -> 0 | J2: =IF(ROW()-1<=0,"",IF(ROW()-1<=$L$2,IFERROR(INDEX(MCQ!$A:$K,ROW()-1+1,10),""),IF(ROW()-1<=$L$2+$M$2,IFERROR(INDEX(CLOZE_AB!$A:$K,ROW()-1-$L$2+1,10),""),IF(ROW()-1<=$L$2+$M$2+$N$2,IFERROR(INDEX(CLOZE_LIST!$A:$K,ROW()-1-$L$2-$M$2+1,10),""),IF(ROW()-1<=$L$2+$M$2+$N$2+$O$2,IFERROR(INDEX(PROFORMA!$A:$K,ROW()-1-$L$2-$M$2-$N$2+1,10),""),""))))) -> 0 | K2: =IF(ROW()-1<=0,"",IF(ROW()-1<=$L$2,IFERROR(INDEX(MCQ!$A:$K,ROW()-1+1,11),""),IF(ROW()-1<=$L$2+$M$2,IFERROR(INDEX(CLOZE_AB!$A:$K,ROW()-1-$L$2+1,11),""),IF(ROW()-1<=$L$2+$M$2+$N$2,IFERROR(INDEX(CLOZE_LIST!$A:$K,ROW()-1-$L$2-$M$2+1,11),""),IF(ROW()-1<=$L$2+$M$2+$N$2+$O$2,IFERROR(INDEX(PROFORMA!$A:$K,ROW()-1-$L$2-$M$2-$N$2+1,11),""),""))))) -> 0 | L2: =COUNTA(MCQ!$A:$A)-1 -> 143 | M2: =COUNTA(CLOZE_AB!$A:$A)-1 -> 168 | N2: =COUNTA(CLOZE_LIST!$A:$A)-1 -> 199 | O2: =COUNTA(PROFORMA!$A:$A)-1 -> 199
A3: =IF(ROW()-1<=0,"",IF(ROW()-1<=$L$2,IFERROR(INDEX(MCQ!$A:$K,ROW()-1+1,1),""),IF(ROW()-1<=$L$2+$M$2,IFERROR(INDEX(CLOZE_AB!$A:$K,ROW()-1-$L$2+1,1),""),IF(ROW()-1<=$L$2+$M$2+$N$2,IFERROR(INDEX(CLOZE_LIST!$A:$K,ROW()-1-$L$2-$M$2+1,1),""),IF(ROW()-1<=$L$2+$M$2+$N$2+$O$2,IFERROR(INDEX(PROFORMA!$A:$K,ROW()-1-$L$2-$M$2-$N$2+1,1),""),""))))) | B3: =IF(ROW()-1<=0,"",IF(ROW()-1<=$L$2,IFERROR(INDEX(MCQ!$A:$K,ROW()-1+1,2),""),IF(ROW()-1<=$L$2+$M$2,IFERROR(INDEX(CLOZE_AB!$A:$K,ROW()-1-$L$2+1,2),""),IF(ROW()-1<=$L$2+$M$2+$N$2,IFERROR(INDEX(CLOZE_LIST!$A:$K,ROW()-1-$L$2-$M$2+1,2),""),IF(ROW()-1<=$L$2+$M$2+$N$2+$O$2,IFERROR(INDEX(PROFORMA!$A:$K,ROW()-1-$L$2-$M$2-$N$2+1,2),""),""))))) -> 0 | C3: =IF(ROW()-1<=0,"",IF(ROW()-1<=$L$2,IFERROR(INDEX(MCQ!$A:$K,ROW()-1+1,3),""),IF(ROW()-1<=$L$2+$M$2,IFERROR(INDEX(CLOZE_AB!$A:$K,ROW()-1-$L$2+1,3),""),IF(ROW()-1<=$L$2+$M$2+$N$2,IFERROR(INDEX(CLOZE_LIST!$A:$K,ROW()-1-$L$2-$M$2+1,3),""),IF(ROW()-1<=$L$2+$M$2+$N$2+$O$2,IFERROR(INDEX(PROFORMA!$A:$K,ROW()-1-$L$2-$M$2-$N$2+1,3),""),""))))) -> 0 | D3: =IF(ROW()-1<=0,"",IF(ROW()-1<=$L$2,IFERROR(INDEX(MCQ!$A:$K,ROW()-1+1,4),""),IF(ROW()-1<=$L$2+$M$2,IFERROR(INDEX(CLOZE_AB!$A:$K,ROW()-1-$L$2+1,4),""),IF(ROW()-1<=$L$2+$M$2+$N$2,IFERROR(INDEX(CLOZE_LIST!$A:$K,ROW()-1-$L$2-$M$2+1,4),""),IF(ROW()-1<=$L$2+$M$2+$N$2+$O$2,IFERROR(INDEX(PROFORMA!$A:$K,ROW()-1-$L$2-$M$2-$N$2+1,4),""),""))))) -> 0 | E3: =IF(ROW()-1<=0,"",IF(ROW()-1<=$L$2,IFERROR(INDEX(MCQ!$A:$K,ROW()-1+1,5),""),IF(ROW()-1<=$L$2+$M$2,IFERROR(INDEX(CLOZE_AB!$A:$K,ROW()-1-$L$2+1,5),""),IF(ROW()-1<=$L$2+$M$2+$N$2,IFERROR(INDEX(CLOZE_LIST!$A:$K,ROW()-1-$L$2-$M$2+1,5),""),IF(ROW()-1<=$L$2+$M$2+$N$2+$O$2,IFERROR(INDEX(PROFORMA!$A:$K,ROW()-1-$L$2-$M$2-$N$2+1,5),""),""))))) -> mcq_radio | F3: =IF(ROW()-1<=0,"",IF(ROW()-1<=$L$2,IFERROR(INDEX(MCQ!$A:$K,ROW()-1+1,6),""),IF(ROW()-1<=$L$2+$M$2,IFERROR(INDEX(CLOZE_AB!$A:$K,ROW()-1-$L$2+1,6),""),IF(ROW()-1<=$L$2+$M$2+$N$2,IFERROR(INDEX(CLOZE_LIST!$A:$K,ROW()-1-$L$2-$M$2+1,6),""),IF(ROW()-1<=$L$2+$M$2+$N$2+$O$2,IFERROR(INDEX(PROFORMA!$A:$K,ROW()-1-$L$2-$M$2-$N$2+1,6),""),""))))) -> 0 | G3: =IF(ROW()-1<=0,"",IF(ROW()-1<=$L$2,IFERROR(INDEX(MCQ!$A:$K,ROW()-1+1,7),""),IF(ROW()-1<=$L$2+$M$2,IFERROR(INDEX(CLOZE_AB!$A:$K,ROW()-1-$L$2+1,7),""),IF(ROW()-1<=$L$2+$M$2+$N$2,IFERROR(INDEX(CLOZE_LIST!$A:$K,ROW()-1-$L$2-$M$2+1,7),""),IF(ROW()-1<=$L$2+$M$2+$N$2+$O$2,IFERROR(INDEX(PROFORMA!$A:$K,ROW()-1-$L$2-$M$2-$N$2+1,7),""),""))))) -> 0 | H3: =IF(ROW()-1<=0,"",IF(ROW()-1<=$L$2,IFERROR(INDEX(MCQ!$A:$K,ROW()-1+1,8),""),IF(ROW()-1<=$L$2+$M$2,IFERROR(INDEX(CLOZE_AB!$A:$K,ROW()-1-$L$2+1,8),""),IF(ROW()-1<=$L$2+$M$2+$N$2,IFERROR(INDEX(CLOZE_LIST!$A:$K,ROW()-1-$L$2-$M$2+1,8),""),IF(ROW()-1<=$L$2+$M$2+$N$2+$O$2,IFERROR(INDEX(PROFORMA!$A:$K,ROW()-1-$L$2-$M$2-$N$2+1,8),""),""))))) -> 0 | I3: =IF(ROW()-1<=0,"",IF(ROW()-1<=$L$2,IFERROR(INDEX(MCQ!$A:$K,ROW()-1+1,9),""),IF(ROW()-1<=$L$2+$M$2,IFERROR(INDEX(CLOZE_AB!$A:$K,ROW()-1-$L$2+1,9),""),IF(ROW()-1<=$L$2+$M$2+$N$2,IFERROR(INDEX(CLOZE_LIST!$A:$K,ROW()-1-$L$2-$M$2+1,9),""),IF(ROW()-1<=$L$2+$M$2+$N$2+$O$2,IFERROR(INDEX(PROFORMA!$A:$K,ROW()-1-$L$2-$M$2-$N$2+1,9),""),""))))) -> 0 | J3: =IF(ROW()-1<=0,"",IF(ROW()-1<=$L$2,IFERROR(INDEX(MCQ!$A:$K,ROW()-1+1,10),""),IF(ROW()-1<=$L$2+$M$2,IFERROR(INDEX(CLOZE_AB!$A:$K,ROW()-1-$L$2+1,10),""),IF(ROW()-1<=$L$2+$M$2+$N$2,IFERROR(INDEX(CLOZE_LIST!$A:$K,ROW()-1-$L$2-$M$2+1,10),""),IF(ROW()-1<=$L$2+$M$2+$N$2+$O$2,IFERROR(INDEX(PROFORMA!$A:$K,ROW()-1-$L$2-$M$2-$N$2+1,10),""),""))))) -> 0 | K3: =IF(ROW()-1<=0,"",IF(ROW()-1<=$L$2,IFERROR(INDEX(MCQ!$A:$K,ROW()-1+1,11),""),IF(ROW()-1<=$L$2+$M$2,IFERROR(INDEX(CLOZE_AB!$A:$K,ROW()-1-$L$2+1,11),""),IF(ROW()-1<=$L$2+$M$2+$N$2,IFERROR(INDEX(CLOZE_LIST!$A:$K,ROW()-1-$L$2-$M$2+1,11),""),IF(ROW()-1<=$L$2+$M$2+$N$2+$O$2,IFERROR(INDEX(PROFORMA!$A:$K,ROW()-1-$L$2-$M$2-$N$2+1,11),""),""))))) -> 0
A4: =IF(ROW()-1<=0,"",IF(ROW()-1<=$L$2,IFERROR(INDEX(MCQ!$A:$K,ROW()-1+1,1),""),IF(ROW()-1<=$L$2+$M$2,IFERROR(INDEX(CLOZE_AB!$A:$K,ROW()-1-$L$2+1,1),""),IF(ROW()-1<=$L$2+$M$2+$N$2,IFERROR(INDEX(CLOZE_LIST!$A:$K,ROW()-1-$L$2-$M$2+1,1),""),IF(ROW()-1<=$L$2+$M$2+$N$2+$O$2,IFERROR(INDEX(PROFORMA!$A:$K,ROW()-1-$L$2-$M$2-$N$2+1,1),""),""))))) | B4: =IF(ROW()-1<=0,"",IF(ROW()-1<=$L$2,IFERROR(INDEX(MCQ!$A:$K,ROW()-1+1,2),""),IF(ROW()-1<=$L$2+$M$2,IFERROR(INDEX(CLOZE_AB!$A:$K,ROW()-1-$L$2+1,2),""),IF(ROW()-1<=$L$2+$M$2+$N$2,IFERROR(INDEX(CLOZE_LIST!$A:$K,ROW()-1-$L$2-$M$2+1,2),""),IF(ROW()-1<=$L$2+$M$2+$N$2+$O$2,IFERROR(INDEX(PROFORMA!$A:$K,ROW()-1-$L$2-$M$2-$N$2+1,2),""),""))))) -> 0 | C4: =IF(ROW()-1<=0,"",IF(ROW()-1<=$L$2,IFERROR(INDEX(MCQ!$A:$K,ROW()-1+1,3),""),IF(ROW()-1<=$L$2+$M$2,IFERROR(INDEX(CLOZE_AB!$A:$K,ROW()-1-$L$2+1,3),""),IF(ROW()-1<=$L$2+$M$2+$N$2,IFERROR(INDEX(CLOZE_LIST!$A:$K,ROW()-1-$L$2-$M$2+1,3),""),IF(ROW()-1<=$L$2+$M$2+$N$2+$O$2,IFERROR(INDEX(PROFORMA!$A:$K,ROW()-1-$L$2-$M$2-$N$2+1,3),""),""))))) -> 0 | D4: =IF(ROW()-1<=0,"",IF(ROW()-1<=$L$2,IFERROR(INDEX(MCQ!$A:$K,ROW()-1+1,4),""),IF(ROW()-1<=$L$2+$M$2,IFERROR(INDEX(CLOZE_AB!$A:$K,ROW()-1-$L$2+1,4),""),IF(ROW()-1<=$L$2+$M$2+$N$2,IFERROR(INDEX(CLOZE_LIST!$A:$K,ROW()-1-$L$2-$M$2+1,4),""),IF(ROW()-1<=$L$2+$M$2+$N$2+$O$2,IFERROR(INDEX(PROFORMA!$A:$K,ROW()-1-$L$2-$M$2-$N$2+1,4),""),""))))) -> 0 | E4: =IF(ROW()-1<=0,"",IF(ROW()-1<=$L$2,IFERROR(INDEX(MCQ!$A:$K,ROW()-1+1,5),""),IF(ROW()-1<=$L$2+$M$2,IFERROR(INDEX(CLOZE_AB!$A:$K,ROW()-1-$L$2+1,5),""),IF(ROW()-1<=$L$2+$M$2+$N$2,IFERROR(INDEX(CLOZE_LIST!$A:$K,ROW()-1-$L$2-$M$2+1,5),""),IF(ROW()-1<=$L$2+$M$2+$N$2+$O$2,IFERROR(INDEX(PROFORMA!$A:$K,ROW()-1-$L$2-$M$2-$N$2+1,5),""),""))))) -> mcq_radio | F4: =IF(ROW()-1<=0,"",IF(ROW()-1<=$L$2,IFERROR(INDEX(MCQ!$A:$K,ROW()-1+1,6),""),IF(ROW()-1<=$L$2+$M$2,IFERROR(INDEX(CLOZE_AB!$A:$K,ROW()-1-$L$2+1,6),""),IF(ROW()-1<=$L$2+$M$2+$N$2,IFERROR(INDEX(CLOZE_LIST!$A:$K,ROW()-1-$L$2-$M$2+1,6),""),IF(ROW()-1<=$L$2+$M$2+$N$2+$O$2,IFERROR(INDEX(PROFORMA!$A:$K,ROW()-1-$L$2-$M$2-$N$2+1,6),""),""))))) -> 0 | G4: =IF(ROW()-1<=0,"",IF(ROW()-1<=$L$2,IFERROR(INDEX(MCQ!$A:$K,ROW()-1+1,7),""),IF(ROW()-1<=$L$2+$M$2,IFERROR(INDEX(CLOZE_AB!$A:$K,ROW()-1-$L$2+1,7),""),IF(ROW()-1<=$L$2+$M$2+$N$2,IFERROR(INDEX(CLOZE_LIST!$A:$K,ROW()-1-$L$2-$M$2+1,7),""),IF(ROW()-1<=$L$2+$M$2+$N$2+$O$2,IFERROR(INDEX(PROFORMA!$A:$K,ROW()-1-$L$2-$M$2-$N$2+1,7),""),""))))) -> 0 | H4: =IF(ROW()-1<=0,"",IF(ROW()-1<=$L$2,IFERROR(INDEX(MCQ!$A:$K,ROW()-1+1,8),""),IF(ROW()-1<=$L$2+$M$2,IFERROR(INDEX(CLOZE_AB!$A:$K,ROW()-1-$L$2+1,8),""),IF(ROW()-1<=$L$2+$M$2+$N$2,IFERROR(INDEX(CLOZE_LIST!$A:$K,ROW()-1-$L$2-$M$2+1,8),""),IF(ROW()-1<=$L$2+$M$2+$N$2+$O$2,IFERROR(INDEX(PROFORMA!$A:$K,ROW()-1-$L$2-$M$2-$N$2+1,8),""),""))))) -> 0 | I4: =IF(ROW()-1<=0,"",IF(ROW()-1<=$L$2,IFERROR(INDEX(MCQ!$A:$K,ROW()-1+1,9),""),IF(ROW()-1<=$L$2+$M$2,IFERROR(INDEX(CLOZE_AB!$A:$K,ROW()-1-$L$2+1,9),""),IF(ROW()-1<=$L$2+$M$2+$N$2,IFERROR(INDEX(CLOZE_LIST!$A:$K,ROW()-1-$L$2-$M$2+1,9),""),IF(ROW()-1<=$L$2+$M$2+$N$2+$O$2,IFERROR(INDEX(PROFORMA!$A:$K,ROW()-1-$L$2-$M$2-$N$2+1,9),""),""))))) -> 0 | J4: =IF(ROW()-1<=0,"",IF(ROW()-1<=$L$2,IFERROR(INDEX(MCQ!$A:$K,ROW()-1+1,10),""),IF(ROW()-1<=$L$2+$M$2,IFERROR(INDEX(CLOZE_AB!$A:$K,ROW()-1-$L$2+1,10),""),IF(ROW()-1<=$L$2+$M$2+$N$2,IFERROR(INDEX(CLOZE_LIST!$A:$K,ROW()-1-$L$2-$M$2+1,10),""),IF(ROW()-1<=$L$2+$M$2+$N$2+$O$2,IFERROR(INDEX(PROFORMA!$A:$K,ROW()-1-$L$2-$M$2-$N$2+1,10),""),""))))) -> 0 | K4: =IF(ROW()-1<=0,"",IF(ROW()-1<=$L$2,IFERROR(INDEX(MCQ!$A:$K,ROW()-1+1,11),""),IF(ROW()-1<=$L$2+$M$2,IFERROR(INDEX(CLOZE_AB!$A:$K,ROW()-1-$L$2+1,11),""),IF(ROW()-1<=$L$2+$M$2+$N$2,IFERROR(INDEX(CLOZE_LIST!$A:$K,ROW()-1-$L$2-$M$2+1,11),""),IF(ROW()-1<=$L$2+$M$2+$N$2+$O$2,IFERROR(INDEX(PROFORMA!$A:$K,ROW()-1-$L$2-$M$2-$N$2+1,11),""),""))))) -> 0
A5: =IF(ROW()-1<=0,"",IF(ROW()-1<=$L$2,IFERROR(INDEX(MCQ!$A:$K,ROW()-1+1,1),""),IF(ROW()-1<=$L$2+$M$2,IFERROR(INDEX(CLOZE_AB!$A:$K,ROW()-1-$L$2+1,1),""),IF(ROW()-1<=$L$2+$M$2+$N$2,IFERROR(INDEX(CLOZE_LIST!$A:$K,ROW()-1-$L$2-$M$2+1,1),""),IF(ROW()-1<=$L$2+$M$2+$N$2+$O$2,IFERROR(INDEX(PROFORMA!$A:$K,ROW()-1-$L$2-$M$2-$N$2+1,1),""),""))))) | B5: =IF(ROW()-1<=0,"",IF(ROW()-1<=$L$2,IFERROR(INDEX(MCQ!$A:$K,ROW()-1+1,2),""),IF(ROW()-1<=$L$2+$M$2,IFERROR(INDEX(CLOZE_AB!$A:$K,ROW()-1-$L$2+1,2),""),IF(ROW()-1<=$L$2+$M$2+$N$2,IFERROR(INDEX(CLOZE_LIST!$A:$K,ROW()-1-$L$2-$M$2+1,2),""),IF(ROW()-1<=$L$2+$M$2+$N$2+$O$2,IFERROR(INDEX(PROFORMA!$A:$K,ROW()-1-$L$2-$M$2-$N$2+1,2),""),""))))) -> 0 | C5: =IF(ROW()-1<=0,"",IF(ROW()-1<=$L$2,IFERROR(INDEX(MCQ!$A:$K,ROW()-1+1,3),""),IF(ROW()-1<=$L$2+$M$2,IFERROR(INDEX(CLOZE_AB!$A:$K,ROW()-1-$L$2+1,3),""),IF(ROW()-1<=$L$2+$M$2+$N$2,IFERROR(INDEX(CLOZE_LIST!$A:$K,ROW()-1-$L$2-$M$2+1,3),""),IF(ROW()-1<=$L$2+$M$2+$N$2+$O$2,IFERROR(INDEX(PROFORMA!$A:$K,ROW()-1-$L$2-$M$2-$N$2+1,3),""),""))))) -> 0 | D5: =IF(ROW()-1<=0,"",IF(ROW()-1<=$L$2,IFERROR(INDEX(MCQ!$A:$K,ROW()-1+1,4),""),IF(ROW()-1<=$L$2+$M$2,IFERROR(INDEX(CLOZE_AB!$A:$K,ROW()-1-$L$2+1,4),""),IF(ROW()-1<=$L$2+$M$2+$N$2,IFERROR(INDEX(CLOZE_LIST!$A:$K,ROW()-1-$L$2-$M$2+1,4),""),IF(ROW()-1<=$L$2+$M$2+$N$2+$O$2,IFERROR(INDEX(PROFORMA!$A:$K,ROW()-1-$L$2-$M$2-$N$2+1,4),""),""))))) -> 0 | E5: =IF(ROW()-1<=0,"",IF(ROW()-1<=$L$2,IFERROR(INDEX(MCQ!$A:$K,ROW()-1+1,5),""),IF(ROW()-1<=$L$2+$M$2,IFERROR(INDEX(CLOZE_AB!$A:$K,ROW()-1-$L$2+1,5),""),IF(ROW()-1<=$L$2+$M$2+$N$2,IFERROR(INDEX(CLOZE_LIST!$A:$K,ROW()-1-$L$2-$M$2+1,5),""),IF(ROW()-1<=$L$2+$M$2+$N$2+$O$2,IFERROR(INDEX(PROFORMA!$A:$K,ROW()-1-$L$2-$M$2-$N$2+1,5),""),""))))) -> mcq_radio | F5: =IF(ROW()-1<=0,"",IF(ROW()-1<=$L$2,IFERROR(INDEX(MCQ!$A:$K,ROW()-1+1,6),""),IF(ROW()-1<=$L$2+$M$2,IFERROR(INDEX(CLOZE_AB!$A:$K,ROW()-1-$L$2+1,6),""),IF(ROW()-1<=$L$2+$M$2+$N$2,IFERROR(INDEX(CLOZE_LIST!$A:$K,ROW()-1-$L$2-$M$2+1,6),""),IF(ROW()-1<=$L$2+$M$2+$N$2+$O$2,IFERROR(INDEX(PROFORMA!$A:$K,ROW()-1-$L$2-$M$2-$N$2+1,6),""),""))))) -> 0 | G5: =IF(ROW()-1<=0,"",IF(ROW()-1<=$L$2,IFERROR(INDEX(MCQ!$A:$K,ROW()-1+1,7),""),IF(ROW()-1<=$L$2+$M$2,IFERROR(INDEX(CLOZE_AB!$A:$K,ROW()-1-$L$2+1,7),""),IF(ROW()-1<=$L$2+$M$2+$N$2,IFERROR(INDEX(CLOZE_LIST!$A:$K,ROW()-1-$L$2-$M$2+1,7),""),IF(ROW()-1<=$L$2+$M$2+$N$2+$O$2,IFERROR(INDEX(PROFORMA!$A:$K,ROW()-1-$L$2-$M$2-$N$2+1,7),""),""))))) -> 0 | H5: =IF(ROW()-1<=0,"",IF(ROW()-1<=$L$2,IFERROR(INDEX(MCQ!$A:$K,ROW()-1+1,8),""),IF(ROW()-1<=$L$2+$M$2,IFERROR(INDEX(CLOZE_AB!$A:$K,ROW()-1-$L$2+1,8),""),IF(ROW()-1<=$L$2+$M$2+$N$2,IFERROR(INDEX(CLOZE_LIST!$A:$K,ROW()-1-$L$2-$M$2+1,8),""),IF(ROW()-1<=$L$2+$M$2+$N$2+$O$2,IFERROR(INDEX(PROFORMA!$A:$K,ROW()-1-$L$2-$M$2-$N$2+1,8),""),""))))) -> 0 | I5: =IF(ROW()-1<=0,"",IF(ROW()-1<=$L$2,IFERROR(INDEX(MCQ!$A:$K,ROW()-1+1,9),""),IF(ROW()-1<=$L$2+$M$2,IFERROR(INDEX(CLOZE_AB!$A:$K,ROW()-1-$L$2+1,9),""),IF(ROW()-1<=$L$2+$M$2+$N$2,IFERROR(INDEX(CLOZE_LIST!$A:$K,ROW()-1-$L$2-$M$2+1,9),""),IF(ROW()-1<=$L$2+$M$2+$N$2+$O$2,IFERROR(INDEX(PROFORMA!$A:$K,ROW()-1-$L$2-$M$2-$N$2+1,9),""),""))))) -> 0 | J5: =IF(ROW()-1<=0,"",IF(ROW()-1<=$L$2,IFERROR(INDEX(MCQ!$A:$K,ROW()-1+1,10),""),IF(ROW()-1<=$L$2+$M$2,IFERROR(INDEX(CLOZE_AB!$A:$K,ROW()-1-$L$2+1,10),""),IF(ROW()-1<=$L$2+$M$2+$N$2,IFERROR(INDEX(CLOZE_LIST!$A:$K,ROW()-1-$L$2-$M$2+1,10),""),IF(ROW()-1<=$L$2+$M$2+$N$2+$O$2,IFERROR(INDEX(PROFORMA!$A:$K,ROW()-1-$L$2-$M$2-$N$2+1,10),""),""))))) -> 0 | K5: =IF(ROW()-1<=0,"",IF(ROW()-1<=$L$2,IFERROR(INDEX(MCQ!$A:$K,ROW()-1+1,11),""),IF(ROW()-1<=$L$2+$M$2,IFERROR(INDEX(CLOZE_AB!$A:$K,ROW()-1-$L$2+1,11),""),IF(ROW()-1<=$L$2+$M$2+$N$2,IFERROR(INDEX(CLOZE_LIST!$A:$K,ROW()-1-$L$2-$M$2+1,11),""),IF(ROW()-1<=$L$2+$M$2+$N$2+$O$2,IFERROR(INDEX(PROFORMA!$A:$K,ROW()-1-$L$2-$M$2-$N$2+1,11),""),""))))) -> 0
A6: =IF(ROW()-1<=0,"",IF(ROW()-1<=$L$2,IFERROR(INDEX(MCQ!$A:$K,ROW()-1+1,1),""),IF(ROW()-1<=$L$2+$M$2,IFERROR(INDEX(CLOZE_AB!$A:$K,ROW()-1-$L$2+1,1),""),IF(ROW()-1<=$L$2+$M$2+$N$2,IFERROR(INDEX(CLOZE_LIST!$A:$K,ROW()-1-$L$2-$M$2+1,1),""),IF(ROW()-1<=$L$2+$M$2+$N$2+$O$2,IFERROR(INDEX(PROFORMA!$A:$K,ROW()-1-$L$2-$M$2-$N$2+1,1),""),""))))) | B6: =IF(ROW()-1<=0,"",IF(ROW()-1<=$L$2,IFERROR(INDEX(MCQ!$A:$K,ROW()-1+1,2),""),IF(ROW()-1<=$L$2+$M$2,IFERROR(INDEX(CLOZE_AB!$A:$K,ROW()-1-$L$2+1,2),""),IF(ROW()-1<=$L$2+$M$2+$N$2,IFERROR(INDEX(CLOZE_LIST!$A:$K,ROW()-1-$L$2-$M$2+1,2),""),IF(ROW()-1<=$L$2+$M$2+$N$2+$O$2,IFERROR(INDEX(PROFORMA!$A:$K,ROW()-1-$L$2-$M$2-$N$2+1,2),""),""))))) -> 0 | C6: =IF(ROW()-1<=0,"",IF(ROW()-1<=$L$2,IFERROR(INDEX(MCQ!$A:$K,ROW()-1+1,3),""),IF(ROW()-1<=$L$2+$M$2,IFERROR(INDEX(CLOZE_AB!$A:$K,ROW()-1-$L$2+1,3),""),IF(ROW()-1<=$L$2+$M$2+$N$2,IFERROR(INDEX(CLOZE_LIST!$A:$K,ROW()-1-$L$2-$M$2+1,3),""),IF(ROW()-1<=$L$2+$M$2+$N$2+$O$2,IFERROR(INDEX(PROFORMA!$A:$K,ROW()-1-$L$2-$M$2-$N$2+1,3),""),""))))) -> 0 | D6: =IF(ROW()-1<=0,"",IF(ROW()-1<=$L$2,IFERROR(INDEX(MCQ!$A:$K,ROW()-1+1,4),""),IF(ROW()-1<=$L$2+$M$2,IFERROR(INDEX(CLOZE_AB!$A:$K,ROW()-1-$L$2+1,4),""),IF(ROW()-1<=$L$2+$M$2+$N$2,IFERROR(INDEX(CLOZE_LIST!$A:$K,ROW()-1-$L$2-$M$2+1,4),""),IF(ROW()-1<=$L$2+$M$2+$N$2+$O$2,IFERROR(INDEX(PROFORMA!$A:$K,ROW()-1-$L$2-$M$2-$N$2+1,4),""),""))))) -> 0 | E6: =IF(ROW()-1<=0,"",IF(ROW()-1<=$L$2,IFERROR(INDEX(MCQ!$A:$K,ROW()-1+1,5),""),IF(ROW()-1<=$L$2+$M$2,IFERROR(INDEX(CLOZE_AB!$A:$K,ROW()-1-$L$2+1,5),""),IF(ROW()-1<=$L$2+$M$2+$N$2,IFERROR(INDEX(CLOZE_LIST!$A:$K,ROW()-1-$L$2-$M$2+1,5),""),IF(ROW()-1<=$L$2+$M$2+$N$2+$O$2,IFERROR(INDEX(PROFORMA!$A:$K,ROW()-1-$L$2-$M$2-$N$2+1,5),""),""))))) -> mcq_radio | F6: =IF(ROW()-1<=0,"",IF(ROW()-1<=$L$2,IFERROR(INDEX(MCQ!$A:$K,ROW()-1+1,6),""),IF(ROW()-1<=$L$2+$M$2,IFERROR(INDEX(CLOZE_AB!$A:$K,ROW()-1-$L$2+1,6),""),IF(ROW()-1<=$L$2+$M$2+$N$2,IFERROR(INDEX(CLOZE_LIST!$A:$K,ROW()-1-$L$2-$M$2+1,6),""),IF(ROW()-1<=$L$2+$M$2+$N$2+$O$2,IFERROR(INDEX(PROFORMA!$A:$K,ROW()-1-$L$2-$M$2-$N$2+1,6),""),""))))) -> 0 | G6: =IF(ROW()-1<=0,"",IF(ROW()-1<=$L$2,IFERROR(INDEX(MCQ!$A:$K,ROW()-1+1,7),""),IF(ROW()-1<=$L$2+$M$2,IFERROR(INDEX(CLOZE_AB!$A:$K,ROW()-1-$L$2+1,7),""),IF(ROW()-1<=$L$2+$M$2+$N$2,IFERROR(INDEX(CLOZE_LIST!$A:$K,ROW()-1-$L$2-$M$2+1,7),""),IF(ROW()-1<=$L$2+$M$2+$N$2+$O$2,IFERROR(INDEX(PROFORMA!$A:$K,ROW()-1-$L$2-$M$2-$N$2+1,7),""),""))))) -> 0 | H6: =IF(ROW()-1<=0,"",IF(ROW()-1<=$L$2,IFERROR(INDEX(MCQ!$A:$K,ROW()-1+1,8),""),IF(ROW()-1<=$L$2+$M$2,IFERROR(INDEX(CLOZE_AB!$A:$K,ROW()-1-$L$2+1,8),""),IF(ROW()-1<=$L$2+$M$2+$N$2,IFERROR(INDEX(CLOZE_LIST!$A:$K,ROW()-1-$L$2-$M$2+1,8),""),IF(ROW()-1<=$L$2+$M$2+$N$2+$O$2,IFERROR(INDEX(PROFORMA!$A:$K,ROW()-1-$L$2-$M$2-$N$2+1,8),""),""))))) -> 0 | I6: =IF(ROW()-1<=0,"",IF(ROW()-1<=$L$2,IFERROR(INDEX(MCQ!$A:$K,ROW()-1+1,9),""),IF(ROW()-1<=$L$2+$M$2,IFERROR(INDEX(CLOZE_AB!$A:$K,ROW()-1-$L$2+1,9),""),IF(ROW()-1<=$L$2+$M$2+$N$2,IFERROR(INDEX(CLOZE_LIST!$A:$K,ROW()-1-$L$2-$M$2+1,9),""),IF(ROW()-1<=$L$2+$M$2+$N$2+$O$2,IFERROR(INDEX(PROFORMA!$A:$K,ROW()-1-$L$2-$M$2-$N$2+1,9),""),""))))) -> 0 | J6: =IF(ROW()-1<=0,"",IF(ROW()-1<=$L$2,IFERROR(INDEX(MCQ!$A:$K,ROW()-1+1,10),""),IF(ROW()-1<=$L$2+$M$2,IFERROR(INDEX(CLOZE_AB!$A:$K,ROW()-1-$L$2+1,10),""),IF(ROW()-1<=$L$2+$M$2+$N$2,IFERROR(INDEX(CLOZE_LIST!$A:$K,ROW()-1-$L$2-$M$2+1,10),""),IF(ROW()-1<=$L$2+$M$2+$N$2+$O$2,IFERROR(INDEX(PROFORMA!$A:$K,ROW()-1-$L$2-$M$2-$N$2+1,10),""),""))))) -> 0 | K6: =IF(ROW()-1<=0,"",IF(ROW()-1<=$L$2,IFERROR(INDEX(MCQ!$A:$K,ROW()-1+1,11),""),IF(ROW()-1<=$L$2+$M$2,IFERROR(INDEX(CLOZE_AB!$A:$K,ROW()-1-$L$2+1,11),""),IF(ROW()-1<=$L$2+$M$2+$N$2,IFERROR(INDEX(CLOZE_LIST!$A:$K,ROW()-1-$L$2-$M$2+1,11),""),IF(ROW()-1<=$L$2+$M$2+$N$2+$O$2,IFERROR(INDEX(PROFORMA!$A:$K,ROW()-1-$L$2-$M$2-$N$2+1,11),""),""))))) -> 0
A7: =IF(ROW()-1<=0,"",IF(ROW()-1<=$L$2,IFERROR(INDEX(MCQ!$A:$K,ROW()-1+1,1),""),IF(ROW()-1<=$L$2+$M$2,IFERROR(INDEX(CLOZE_AB!$A:$K,ROW()-1-$L$2+1,1),""),IF(ROW()-1<=$L$2+$M$2+$N$2,IFERROR(INDEX(CLOZE_LIST!$A:$K,ROW()-1-$L$2-$M$2+1,1),""),IF(ROW()-1<=$L$2+$M$2+$N$2+$O$2,IFERROR(INDEX(PROFORMA!$A:$K,ROW()-1-$L$2-$M$2-$N$2+1,1),""),""))))) | B7: =IF(ROW()-1<=0,"",IF(ROW()-1<=$L$2,IFERROR(INDEX(MCQ!$A:$K,ROW()-1+1,2),""),IF(ROW()-1<=$L$2+$M$2,IFERROR(INDEX(CLOZE_AB!$A:$K,ROW()-1-$L$2+1,2),""),IF(ROW()-1<=$L$2+$M$2+$N$2,IFERROR(INDEX(CLOZE_LIST!$A:$K,ROW()-1-$L$2-$M$2+1,2),""),IF(ROW()-1<=$L$2+$M$2+$N$2+$O$2,IFERROR(INDEX(PROFORMA!$A:$K,ROW()-1-$L$2-$M$2-$N$2+1,2),""),""))))) -> 0 | C7: =IF(ROW()-1<=0,"",IF(ROW()-1<=$L$2,IFERROR(INDEX(MCQ!$A:$K,ROW()-1+1,3),""),IF(ROW()-1<=$L$2+$M$2,IFERROR(INDEX(CLOZE_AB!$A:$K,ROW()-1-$L$2+1,3),""),IF(ROW()-1<=$L$2+$M$2+$N$2,IFERROR(INDEX(CLOZE_LIST!$A:$K,ROW()-1-$L$2-$M$2+1,3),""),IF(ROW()-1<=$L$2+$M$2+$N$2+$O$2,IFERROR(INDEX(PROFORMA!$A:$K,ROW()-1-$L$2-$M$2-$N$2+1,3),""),""))))) -> 0 | D7: =IF(ROW()-1<=0,"",IF(ROW()-1<=$L$2,IFERROR(INDEX(MCQ!$A:$K,ROW()-1+1,4),""),IF(ROW()-1<=$L$2+$M$2,IFERROR(INDEX(CLOZE_AB!$A:$K,ROW()-1-$L$2+1,4),""),IF(ROW()-1<=$L$2+$M$2+$N$2,IFERROR(INDEX(CLOZE_LIST!$A:$K,ROW()-1-$L$2-$M$2+1,4),""),IF(ROW()-1<=$L$2+$M$2+$N$2+$O$2,IFERROR(INDEX(PROFORMA!$A:$K,ROW()-1-$L$2-$M$2-$N$2+1,4),""),""))))) -> 0 | E7: =IF(ROW()-1<=0,"",IF(ROW()-1<=$L$2,IFERROR(INDEX(MCQ!$A:$K,ROW()-1+1,5),""),IF(ROW()-1<=$L$2+$M$2,IFERROR(INDEX(CLOZE_AB!$A:$K,ROW()-1-$L$2+1,5),""),IF(ROW()-1<=$L$2+$M$2+$N$2,IFERROR(INDEX(CLOZE_LIST!$A:$K,ROW()-1-$L$2-$M$2+1,5),""),IF(ROW()-1<=$L$2+$M$2+$N$2+$O$2,IFERROR(INDEX(PROFORMA!$A:$K,ROW()-1-$L$2-$M$2-$N$2+1,5),""),""))))) -> mcq_radio | F7: =IF(ROW()-1<=0,"",IF(ROW()-1<=$L$2,IFERROR(INDEX(MCQ!$A:$K,ROW()-1+1,6),""),IF(ROW()-1<=$L$2+$M$2,IFERROR(INDEX(CLOZE_AB!$A:$K,ROW()-1-$L$2+1,6),""),IF(ROW()-1<=$L$2+$M$2+$N$2,IFERROR(INDEX(CLOZE_LIST!$A:$K,ROW()-1-$L$2-$M$2+1,6),""),IF(ROW()-1<=$L$2+$M$2+$N$2+$O$2,IFERROR(INDEX(PROFORMA!$A:$K,ROW()-1-$L$2-$M$2-$N$2+1,6),""),""))))) -> 0 | G7: =IF(ROW()-1<=0,"",IF(ROW()-1<=$L$2,IFERROR(INDEX(MCQ!$A:$K,ROW()-1+1,7),""),IF(ROW()-1<=$L$2+$M$2,IFERROR(INDEX(CLOZE_AB!$A:$K,ROW()-1-$L$2+1,7),""),IF(ROW()-1<=$L$2+$M$2+$N$2,IFERROR(INDEX(CLOZE_LIST!$A:$K,ROW()-1-$L$2-$M$2+1,7),""),IF(ROW()-1<=$L$2+$M$2+$N$2+$O$2,IFERROR(INDEX(PROFORMA!$A:$K,ROW()-1-$L$2-$M$2-$N$2+1,7),""),""))))) -> 0 | H7: =IF(ROW()-1<=0,"",IF(ROW()-1<=$L$2,IFERROR(INDEX(MCQ!$A:$K,ROW()-1+1,8),""),IF(ROW()-1<=$L$2+$M$2,IFERROR(INDEX(CLOZE_AB!$A:$K,ROW()-1-$L$2+1,8),""),IF(ROW()-1<=$L$2+$M$2+$N$2,IFERROR(INDEX(CLOZE_LIST!$A:$K,ROW()-1-$L$2-$M$2+1,8),""),IF(ROW()-1<=$L$2+$M$2+$N$2+$O$2,IFERROR(INDEX(PROFORMA!$A:$K,ROW()-1-$L$2-$M$2-$N$2+1,8),""),""))))) -> 0 | I7: =IF(ROW()-1<=0,"",IF(ROW()-1<=$L$2,IFERROR(INDEX(MCQ!$A:$K,ROW()-1+1,9),""),IF(ROW()-1<=$L$2+$M$2,IFERROR(INDEX(CLOZE_AB!$A:$K,ROW()-1-$L$2+1,9),""),IF(ROW()-1<=$L$2+$M$2+$N$2,IFERROR(INDEX(CLOZE_LIST!$A:$K,ROW()-1-$L$2-$M$2+1,9),""),IF(ROW()-1<=$L$2+$M$2+$N$2+$O$2,IFERROR(INDEX(PROFORMA!$A:$K,ROW()-1-$L$2-$M$2-$N$2+1,9),""),""))))) -> 0 | J7: =IF(ROW()-1<=0,"",IF(ROW()-1<=$L$2,IFERROR(INDEX(MCQ!$A:$K,ROW()-1+1,10),""),IF(ROW()-1<=$L$2+$M$2,IFERROR(INDEX(CLOZE_AB!$A:$K,ROW()-1-$L$2+1,10),""),IF(ROW()-1<=$L$2+$M$2+$N$2,IFERROR(INDEX(CLOZE_LIST!$A:$K,ROW()-1-$L$2-$M$2+1,10),""),IF(ROW()-1<=$L$2+$M$2+$N$2+$O$2,IFERROR(INDEX(PROFORMA!$A:$K,ROW()-1-$L$2-$M$2-$N$2+1,10),""),""))))) -> 0 | K7: =IF(ROW()-1<=0,"",IF(ROW()-1<=$L$2,IFERROR(INDEX(MCQ!$A:$K,ROW()-1+1,11),""),IF(ROW()-1<=$L$2+$M$2,IFERROR(INDEX(CLOZE_AB!$A:$K,ROW()-1-$L$2+1,11),""),IF(ROW()-1<=$L$2+$M$2+$N$2,IFERROR(INDEX(CLOZE_LIST!$A:$K,ROW()-1-$L$2-$M$2+1,11),""),IF(ROW()-1<=$L$2+$M$2+$N$2+$O$2,IFERROR(INDEX(PROFORMA!$A:$K,ROW()-1-$L$2-$M$2-$N$2+1,11),""),""))))) -> 0
A8: =IF(ROW()-1<=0,"",IF(ROW()-1<=$L$2,IFERROR(INDEX(MCQ!$A:$K,ROW()-1+1,1),""),IF(ROW()-1<=$L$2+$M$2,IFERROR(INDEX(CLOZE_AB!$A:$K,ROW()-1-$L$2+1,1),""),IF(ROW()-1<=$L$2+$M$2+$N$2,IFERROR(INDEX(CLOZE_LIST!$A:$K,ROW()-1-$L$2-$M$2+1,1),""),IF(ROW()-1<=$L$2+$M$2+$N$2+$O$2,IFERROR(INDEX(PROFORMA!$A:$K,ROW()-1-$L$2-$M$2-$N$2+1,1),""),""))))) | B8: =IF(ROW()-1<=0,"",IF(ROW()-1<=$L$2,IFERROR(INDEX(MCQ!$A:$K,ROW()-1+1,2),""),IF(ROW()-1<=$L$2+$M$2,IFERROR(INDEX(CLOZE_AB!$A:$K,ROW()-1-$L$2+1,2),""),IF(ROW()-1<=$L$2+$M$2+$N$2,IFERROR(INDEX(CLOZE_LIST!$A:$K,ROW()-1-$L$2-$M$2+1,2),""),IF(ROW()-1<=$L$2+$M$2+$N$2+$O$2,IFERROR(INDEX(PROFORMA!$A:$K,ROW()-1-$L$2-$M$2-$N$2+1,2),""),""))))) -> 0 | C8: =IF(ROW()-1<=0,"",IF(ROW()-1<=$L$2,IFERROR(INDEX(MCQ!$A:$K,ROW()-1+1,3),""),IF(ROW()-1<=$L$2+$M$2,IFERROR(INDEX(CLOZE_AB!$A:$K,ROW()-1-$L$2+1,3),""),IF(ROW()-1<=$L$2+$M$2+$N$2,IFERROR(INDEX(CLOZE_LIST!$A:$K,ROW()-1-$L$2-$M$2+1,3),""),IF(ROW()-1<=$L$2+$M$2+$N$2+$O$2,IFERROR(INDEX(PROFORMA!$A:$K,ROW()-1-$L$2-$M$2-$N$2+1,3),""),""))))) -> 0 | D8: =IF(ROW()-1<=0,"",IF(ROW()-1<=$L$2,IFERROR(INDEX(MCQ!$A:$K,ROW()-1+1,4),""),IF(ROW()-1<=$L$2+$M$2,IFERROR(INDEX(CLOZE_AB!$A:$K,ROW()-1-$L$2+1,4),""),IF(ROW()-1<=$L$2+$M$2+$N$2,IFERROR(INDEX(CLOZE_LIST!$A:$K,ROW()-1-$L$2-$M$2+1,4),""),IF(ROW()-1<=$L$2+$M$2+$N$2+$O$2,IFERROR(INDEX(PROFORMA!$A:$K,ROW()-1-$L$2-$M$2-$N$2+1,4),""),""))))) -> 0 | E8: =IF(ROW()-1<=0,"",IF(ROW()-1<=$L$2,IFERROR(INDEX(MCQ!$A:$K,ROW()-1+1,5),""),IF(ROW()-1<=$L$2+$M$2,IFERROR(INDEX(CLOZE_AB!$A:$K,ROW()-1-$L$2+1,5),""),IF(ROW()-1<=$L$2+$M$2+$N$2,IFERROR(INDEX(CLOZE_LIST!$A:$K,ROW()-1-$L$2-$M$2+1,5),""),IF(ROW()-1<=$L$2+$M$2+$N$2+$O$2,IFERROR(INDEX(PROFORMA!$A:$K,ROW()-1-$L$2-$M$2-$N$2+1,5),""),""))))) -> mcq_radio | F8: =IF(ROW()-1<=0,"",IF(ROW()-1<=$L$2,IFERROR(INDEX(MCQ!$A:$K,ROW()-1+1,6),""),IF(ROW()-1<=$L$2+$M$2,IFERROR(INDEX(CLOZE_AB!$A:$K,ROW()-1-$L$2+1,6),""),IF(ROW()-1<=$L$2+$M$2+$N$2,IFERROR(INDEX(CLOZE_LIST!$A:$K,ROW()-1-$L$2-$M$2+1,6),""),IF(ROW()-1<=$L$2+$M$2+$N$2+$O$2,IFERROR(INDEX(PROFORMA!$A:$K,ROW()-1-$L$2-$M$2-$N$2+1,6),""),""))))) -> 0 | G8: =IF(ROW()-1<=0,"",IF(ROW()-1<=$L$2,IFERROR(INDEX(MCQ!$A:$K,ROW()-1+1,7),""),IF(ROW()-1<=$L$2+$M$2,IFERROR(INDEX(CLOZE_AB!$A:$K,ROW()-1-$L$2+1,7),""),IF(ROW()-1<=$L$2+$M$2+$N$2,IFERROR(INDEX(CLOZE_LIST!$A:$K,ROW()-1-$L$2-$M$2+1,7),""),IF(ROW()-1<=$L$2+$M$2+$N$2+$O$2,IFERROR(INDEX(PROFORMA!$A:$K,ROW()-1-$L$2-$M$2-$N$2+1,7),""),""))))) -> 0 | H8: =IF(ROW()-1<=0,"",IF(ROW()-1<=$L$2,IFERROR(INDEX(MCQ!$A:$K,ROW()-1+1,8),""),IF(ROW()-1<=$L$2+$M$2,IFERROR(INDEX(CLOZE_AB!$A:$K,ROW()-1-$L$2+1,8),""),IF(ROW()-1<=$L$2+$M$2+$N$2,IFERROR(INDEX(CLOZE_LIST!$A:$K,ROW()-1-$L$2-$M$2+1,8),""),IF(ROW()-1<=$L$2+$M$2+$N$2+$O$2,IFERROR(INDEX(PROFORMA!$A:$K,ROW()-1-$L$2-$M$2-$N$2+1,8),""),""))))) -> 0 | I8: =IF(ROW()-1<=0,"",IF(ROW()-1<=$L$2,IFERROR(INDEX(MCQ!$A:$K,ROW()-1+1,9),""),IF(ROW()-1<=$L$2+$M$2,IFERROR(INDEX(CLOZE_AB!$A:$K,ROW()-1-$L$2+1,9),""),IF(ROW()-1<=$L$2+$M$2+$N$2,IFERROR(INDEX(CLOZE_LIST!$A:$K,ROW()-1-$L$2-$M$2+1,9),""),IF(ROW()-1<=$L$2+$M$2+$N$2+$O$2,IFERROR(INDEX(PROFORMA!$A:$K,ROW()-1-$L$2-$M$2-$N$2+1,9),""),""))))) -> 0 | J8: =IF(ROW()-1<=0,"",IF(ROW()-1<=$L$2,IFERROR(INDEX(MCQ!$A:$K,ROW()-1+1,10),""),IF(ROW()-1<=$L$2+$M$2,IFERROR(INDEX(CLOZE_AB!$A:$K,ROW()-1-$L$2+1,10),""),IF(ROW()-1<=$L$2+$M$2+$N$2,IFERROR(INDEX(CLOZE_LIST!$A:$K,ROW()-1-$L$2-$M$2+1,10),""),IF(ROW()-1<=$L$2+$M$2+$N$2+$O$2,IFERROR(INDEX(PROFORMA!$A:$K,ROW()-1-$L$2-$M$2-$N$2+1,10),""),""))))) -> 0 | K8: =IF(ROW()-1<=0,"",IF(ROW()-1<=$L$2,IFERROR(INDEX(MCQ!$A:$K,ROW()-1+1,11),""),IF(ROW()-1<=$L$2+$M$2,IFERROR(INDEX(CLOZE_AB!$A:$K,ROW()-1-$L$2+1,11),""),IF(ROW()-1<=$L$2+$M$2+$N$2,IFERROR(INDEX(CLOZE_LIST!$A:$K,ROW()-1-$L$2-$M$2+1,11),""),IF(ROW()-1<=$L$2+$M$2+$N$2+$O$2,IFERROR(INDEX(PROFORMA!$A:$K,ROW()-1-$L$2-$M$2-$N$2+1,11),""),""))))) -> 0
A9: =IF(ROW()-1<=0,"",IF(ROW()-1<=$L$2,IFERROR(INDEX(MCQ!$A:$K,ROW()-1+1,1),""),IF(ROW()-1<=$L$2+$M$2,IFERROR(INDEX(CLOZE_AB!$A:$K,ROW()-1-$L$2+1,1),""),IF(ROW()-1<=$L$2+$M$2+$N$2,IFERROR(INDEX(CLOZE_LIST!$A:$K,ROW()-1-$L$2-$M$2+1,1),""),IF(ROW()-1<=$L$2+$M$2+$N$2+$O$2,IFERROR(INDEX(PROFORMA!$A:$K,ROW()-1-$L$2-$M$2-$N$2+1,1),""),""))))) | B9: =IF(ROW()-1<=0,"",IF(ROW()-1<=$L$2,IFERROR(INDEX(MCQ!$A:$K,ROW()-1+1,2),""),IF(ROW()-1<=$L$2+$M$2,IFERROR(INDEX(CLOZE_AB!$A:$K,ROW()-1-$L$2+1,2),""),IF(ROW()-1<=$L$2+$M$2+$N$2,IFERROR(INDEX(CLOZE_LIST!$A:$K,ROW()-1-$L$2-$M$2+1,2),""),IF(ROW()-1<=$L$2+$M$2+$N$2+$O$2,IFERROR(INDEX(PROFORMA!$A:$K,ROW()-1-$L$2-$M$2-$N$2+1,2),""),""))))) -> 0 | C9: =IF(ROW()-1<=0,"",IF(ROW()-1<=$L$2,IFERROR(INDEX(MCQ!$A:$K,ROW()-1+1,3),""),IF(ROW()-1<=$L$2+$M$2,IFERROR(INDEX(CLOZE_AB!$A:$K,ROW()-1-$L$2+1,3),""),IF(ROW()-1<=$L$2+$M$2+$N$2,IFERROR(INDEX(CLOZE_LIST!$A:$K,ROW()-1-$L$2-$M$2+1,3),""),IF(ROW()-1<=$L$2+$M$2+$N$2+$O$2,IFERROR(INDEX(PROFORMA!$A:$K,ROW()-1-$L$2-$M$2-$N$2+1,3),""),""))))) -> 0 | D9: =IF(ROW()-1<=0,"",IF(ROW()-1<=$L$2,IFERROR(INDEX(MCQ!$A:$K,ROW()-1+1,4),""),IF(ROW()-1<=$L$2+$M$2,IFERROR(INDEX(CLOZE_AB!$A:$K,ROW()-1-$L$2+1,4),""),IF(ROW()-1<=$L$2+$M$2+$N$2,IFERROR(INDEX(CLOZE_LIST!$A:$K,ROW()-1-$L$2-$M$2+1,4),""),IF(ROW()-1<=$L$2+$M$2+$N$2+$O$2,IFERROR(INDEX(PROFORMA!$A:$K,ROW()-1-$L$2-$M$2-$N$2+1,4),""),""))))) -> 0 | E9: =IF(ROW()-1<=0,"",IF(ROW()-1<=$L$2,IFERROR(INDEX(MCQ!$A:$K,ROW()-1+1,5),""),IF(ROW()-1<=$L$2+$M$2,IFERROR(INDEX(CLOZE_AB!$A:$K,ROW()-1-$L$2+1,5),""),IF(ROW()-1<=$L$2+$M$2+$N$2,IFERROR(INDEX(CLOZE_LIST!$A:$K,ROW()-1-$L$2-$M$2+1,5),""),IF(ROW()-1<=$L$2+$M$2+$N$2+$O$2,IFERROR(INDEX(PROFORMA!$A:$K,ROW()-1-$L$2-$M$2-$N$2+1,5),""),""))))) -> mcq_radio | F9: =IF(ROW()-1<=0,"",IF(ROW()-1<=$L$2,IFERROR(INDEX(MCQ!$A:$K,ROW()-1+1,6),""),IF(ROW()-1<=$L$2+$M$2,IFERROR(INDEX(CLOZE_AB!$A:$K,ROW()-1-$L$2+1,6),""),IF(ROW()-1<=$L$2+$M$2+$N$2,IFERROR(INDEX(CLOZE_LIST!$A:$K,ROW()-1-$L$2-$M$2+1,6),""),IF(ROW()-1<=$L$2+$M$2+$N$2+$O$2,IFERROR(INDEX(PROFORMA!$A:$K,ROW()-1-$L$2-$M$2-$N$2+1,6),""),""))))) -> 0 | G9: =IF(ROW()-1<=0,"",IF(ROW()-1<=$L$2,IFERROR(INDEX(MCQ!$A:$K,ROW()-1+1,7),""),IF(ROW()-1<=$L$2+$M$2,IFERROR(INDEX(CLOZE_AB!$A:$K,ROW()-1-$L$2+1,7),""),IF(ROW()-1<=$L$2+$M$2+$N$2,IFERROR(INDEX(CLOZE_LIST!$A:$K,ROW()-1-$L$2-$M$2+1,7),""),IF(ROW()-1<=$L$2+$M$2+$N$2+$O$2,IFERROR(INDEX(PROFORMA!$A:$K,ROW()-1-$L$2-$M$2-$N$2+1,7),""),""))))) -> 0 | H9: =IF(ROW()-1<=0,"",IF(ROW()-1<=$L$2,IFERROR(INDEX(MCQ!$A:$K,ROW()-1+1,8),""),IF(ROW()-1<=$L$2+$M$2,IFERROR(INDEX(CLOZE_AB!$A:$K,ROW()-1-$L$2+1,8),""),IF(ROW()-1<=$L$2+$M$2+$N$2,IFERROR(INDEX(CLOZE_LIST!$A:$K,ROW()-1-$L$2-$M$2+1,8),""),IF(ROW()-1<=$L$2+$M$2+$N$2+$O$2,IFERROR(INDEX(PROFORMA!$A:$K,ROW()-1-$L$2-$M$2-$N$2+1,8),""),""))))) -> 0 | I9: =IF(ROW()-1<=0,"",IF(ROW()-1<=$L$2,IFERROR(INDEX(MCQ!$A:$K,ROW()-1+1,9),""),IF(ROW()-1<=$L$2+$M$2,IFERROR(INDEX(CLOZE_AB!$A:$K,ROW()-1-$L$2+1,9),""),IF(ROW()-1<=$L$2+$M$2+$N$2,IFERROR(INDEX(CLOZE_LIST!$A:$K,ROW()-1-$L$2-$M$2+1,9),""),IF(ROW()-1<=$L$2+$M$2+$N$2+$O$2,IFERROR(INDEX(PROFORMA!$A:$K,ROW()-1-$L$2-$M$2-$N$2+1,9),""),""))))) -> 0 | J9: =IF(ROW()-1<=0,"",IF(ROW()-1<=$L$2,IFERROR(INDEX(MCQ!$A:$K,ROW()-1+1,10),""),IF(ROW()-1<=$L$2+$M$2,IFERROR(INDEX(CLOZE_AB!$A:$K,ROW()-1-$L$2+1,10),""),IF(ROW()-1<=$L$2+$M$2+$N$2,IFERROR(INDEX(CLOZE_LIST!$A:$K,ROW()-1-$L$2-$M$2+1,10),""),IF(ROW()-1<=$L$2+$M$2+$N$2+$O$2,IFERROR(INDEX(PROFORMA!$A:$K,ROW()-1-$L$2-$M$2-$N$2+1,10),""),""))))) -> 0 | K9: =IF(ROW()-1<=0,"",IF(ROW()-1<=$L$2,IFERROR(INDEX(MCQ!$A:$K,ROW()-1+1,11),""),IF(ROW()-1<=$L$2+$M$2,IFERROR(INDEX(CLOZE_AB!$A:$K,ROW()-1-$L$2+1,11),""),IF(ROW()-1<=$L$2+$M$2+$N$2,IFERROR(INDEX(CLOZE_LIST!$A:$K,ROW()-1-$L$2-$M$2+1,11),""),IF(ROW()-1<=$L$2+$M$2+$N$2+$O$2,IFERROR(INDEX(PROFORMA!$A:$K,ROW()-1-$L$2-$M$2-$N$2+1,11),""),""))))) -> 0
A10: =IF(ROW()-1<=0,"",IF(ROW()-1<=$L$2,IFERROR(INDEX(MCQ!$A:$K,ROW()-1+1,1),""),IF(ROW()-1<=$L$2+$M$2,IFERROR(INDEX(CLOZE_AB!$A:$K,ROW()-1-$L$2+1,1),""),IF(ROW()-1<=$L$2+$M$2+$N$2,IFERROR(INDEX(CLOZE_LIST!$A:$K,ROW()-1-$L$2-$M$2+1,1),""),IF(ROW()-1<=$L$2+$M$2+$N$2+$O$2,IFERROR(INDEX(PROFORMA!$A:$K,ROW()-1-$L$2-$M$2-$N$2+1,1),""),""))))) | B10: =IF(ROW()-1<=0,"",IF(ROW()-1<=$L$2,IFERROR(INDEX(MCQ!$A:$K,ROW()-1+1,2),""),IF(ROW()-1<=$L$2+$M$2,IFERROR(INDEX(CLOZE_AB!$A:$K,ROW()-1-$L$2+1,2),""),IF(ROW()-1<=$L$2+$M$2+$N$2,IFERROR(INDEX(CLOZE_LIST!$A:$K,ROW()-1-$L$2-$M$2+1,2),""),IF(ROW()-1<=$L$2+$M$2+$N$2+$O$2,IFERROR(INDEX(PROFORMA!$A:$K,ROW()-1-$L$2-$M$2-$N$2+1,2),""),""))))) -> 0 | C10: =IF(ROW()-1<=0,"",IF(ROW()-1<=$L$2,IFERROR(INDEX(MCQ!$A:$K,ROW()-1+1,3),""),IF(ROW()-1<=$L$2+$M$2,IFERROR(INDEX(CLOZE_AB!$A:$K,ROW()-1-$L$2+1,3),""),IF(ROW()-1<=$L$2+$M$2+$N$2,IFERROR(INDEX(CLOZE_LIST!$A:$K,ROW()-1-$L$2-$M$2+1,3),""),IF(ROW()-1<=$L$2+$M$2+$N$2+$O$2,IFERROR(INDEX(PROFORMA!$A:$K,ROW()-1-$L$2-$M$2-$N$2+1,3),""),""))))) -> 0 | D10: =IF(ROW()-1<=0,"",IF(ROW()-1<=$L$2,IFERROR(INDEX(MCQ!$A:$K,ROW()-1+1,4),""),IF(ROW()-1<=$L$2+$M$2,IFERROR(INDEX(CLOZE_AB!$A:$K,ROW()-1-$L$2+1,4),""),IF(ROW()-1<=$L$2+$M$2+$N$2,IFERROR(INDEX(CLOZE_LIST!$A:$K,ROW()-1-$L$2-$M$2+1,4),""),IF(ROW()-1<=$L$2+$M$2+$N$2+$O$2,IFERROR(INDEX(PROFORMA!$A:$K,ROW()-1-$L$2-$M$2-$N$2+1,4),""),""))))) -> 0 | E10: =IF(ROW()-1<=0,"",IF(ROW()-1<=$L$2,IFERROR(INDEX(MCQ!$A:$K,ROW()-1+1,5),""),IF(ROW()-1<=$L$2+$M$2,IFERROR(INDEX(CLOZE_AB!$A:$K,ROW()-1-$L$2+1,5),""),IF(ROW()-1<=$L$2+$M$2+$N$2,IFERROR(INDEX(CLOZE_LIST!$A:$K,ROW()-1-$L$2-$M$2+1,5),""),IF(ROW()-1<=$L$2+$M$2+$N$2+$O$2,IFERROR(INDEX(PROFORMA!$A:$K,ROW()-1-$L$2-$M$2-$N$2+1,5),""),""))))) -> mcq_radio | F10: =IF(ROW()-1<=0,"",IF(ROW()-1<=$L$2,IFERROR(INDEX(MCQ!$A:$K,ROW()-1+1,6),""),IF(ROW()-1<=$L$2+$M$2,IFERROR(INDEX(CLOZE_AB!$A:$K,ROW()-1-$L$2+1,6),""),IF(ROW()-1<=$L$2+$M$2+$N$2,IFERROR(INDEX(CLOZE_LIST!$A:$K,ROW()-1-$L$2-$M$2+1,6),""),IF(ROW()-1<=$L$2+$M$2+$N$2+$O$2,IFERROR(INDEX(PROFORMA!$A:$K,ROW()-1-$L$2-$M$2-$N$2+1,6),""),""))))) -> 0 | G10: =IF(ROW()-1<=0,"",IF(ROW()-1<=$L$2,IFERROR(INDEX(MCQ!$A:$K,ROW()-1+1,7),""),IF(ROW()-1<=$L$2+$M$2,IFERROR(INDEX(CLOZE_AB!$A:$K,ROW()-1-$L$2+1,7),""),IF(ROW()-1<=$L$2+$M$2+$N$2,IFERROR(INDEX(CLOZE_LIST!$A:$K,ROW()-1-$L$2-$M$2+1,7),""),IF(ROW()-1<=$L$2+$M$2+$N$2+$O$2,IFERROR(INDEX(PROFORMA!$A:$K,ROW()-1-$L$2-$M$2-$N$2+1,7),""),""))))) -> 0 | H10: =IF(ROW()-1<=0,"",IF(ROW()-1<=$L$2,IFERROR(INDEX(MCQ!$A:$K,ROW()-1+1,8),""),IF(ROW()-1<=$L$2+$M$2,IFERROR(INDEX(CLOZE_AB!$A:$K,ROW()-1-$L$2+1,8),""),IF(ROW()-1<=$L$2+$M$2+$N$2,IFERROR(INDEX(CLOZE_LIST!$A:$K,ROW()-1-$L$2-$M$2+1,8),""),IF(ROW()-1<=$L$2+$M$2+$N$2+$O$2,IFERROR(INDEX(PROFORMA!$A:$K,ROW()-1-$L$2-$M$2-$N$2+1,8),""),""))))) -> 0 | I10: =IF(ROW()-1<=0,"",IF(ROW()-1<=$L$2,IFERROR(INDEX(MCQ!$A:$K,ROW()-1+1,9),""),IF(ROW()-1<=$L$2+$M$2,IFERROR(INDEX(CLOZE_AB!$A:$K,ROW()-1-$L$2+1,9),""),IF(ROW()-1<=$L$2+$M$2+$N$2,IFERROR(INDEX(CLOZE_LIST!$A:$K,ROW()-1-$L$2-$M$2+1,9),""),IF(ROW()-1<=$L$2+$M$2+$N$2+$O$2,IFERROR(INDEX(PROFORMA!$A:$K,ROW()-1-$L$2-$M$2-$N$2+1,9),""),""))))) -> 0 | J10: =IF(ROW()-1<=0,"",IF(ROW()-1<=$L$2,IFERROR(INDEX(MCQ!$A:$K,ROW()-1+1,10),""),IF(ROW()-1<=$L$2+$M$2,IFERROR(INDEX(CLOZE_AB!$A:$K,ROW()-1-$L$2+1,10),""),IF(ROW()-1<=$L$2+$M$2+$N$2,IFERROR(INDEX(CLOZE_LIST!$A:$K,ROW()-1-$L$2-$M$2+1,10),""),IF(ROW()-1<=$L$2+$M$2+$N$2+$O$2,IFERROR(INDEX(PROFORMA!$A:$K,ROW()-1-$L$2-$M$2-$N$2+1,10),""),""))))) -> 0 | K10: =IF(ROW()-1<=0,"",IF(ROW()-1<=$L$2,IFERROR(INDEX(MCQ!$A:$K,ROW()-1+1,11),""),IF(ROW()-1<=$L$2+$M$2,IFERROR(INDEX(CLOZE_AB!$A:$K,ROW()-1-$L$2+1,11),""),IF(ROW()-1<=$L$2+$M$2+$N$2,IFERROR(INDEX(CLOZE_LIST!$A:$K,ROW()-1-$L$2-$M$2+1,11),""),IF(ROW()-1<=$L$2+$M$2+$N$2+$O$2,IFERROR(INDEX(PROFORMA!$A:$K,ROW()-1-$L$2-$M$2-$N$2+1,11),""),""))))) -> 0
A11: =IF(ROW()-1<=0,"",IF(ROW()-1<=$L$2,IFERROR(INDEX(MCQ!$A:$K,ROW()-1+1,1),""),IF(ROW()-1<=$L$2+$M$2,IFERROR(INDEX(CLOZE_AB!$A:$K,ROW()-1-$L$2+1,1),""),IF(ROW()-1<=$L$2+$M$2+$N$2,IFERROR(INDEX(CLOZE_LIST!$A:$K,ROW()-1-$L$2-$M$2+1,1),""),IF(ROW()-1<=$L$2+$M$2+$N$2+$O$2,IFERROR(INDEX(PROFORMA!$A:$K,ROW()-1-$L$2-$M$2-$N$2+1,1),""),""))))) | B11: =IF(ROW()-1<=0,"",IF(ROW()-1<=$L$2,IFERROR(INDEX(MCQ!$A:$K,ROW()-1+1,2),""),IF(ROW()-1<=$L$2+$M$2,IFERROR(INDEX(CLOZE_AB!$A:$K,ROW()-1-$L$2+1,2),""),IF(ROW()-1<=$L$2+$M$2+$N$2,IFERROR(INDEX(CLOZE_LIST!$A:$K,ROW()-1-$L$2-$M$2+1,2),""),IF(ROW()-1<=$L$2+$M$2+$N$2+$O$2,IFERROR(INDEX(PROFORMA!$A:$K,ROW()-1-$L$2-$M$2-$N$2+1,2),""),""))))) -> 0 | C11: =IF(ROW()-1<=0,"",IF(ROW()-1<=$L$2,IFERROR(INDEX(MCQ!$A:$K,ROW()-1+1,3),""),IF(ROW()-1<=$L$2+$M$2,IFERROR(INDEX(CLOZE_AB!$A:$K,ROW()-1-$L$2+1,3),""),IF(ROW()-1<=$L$2+$M$2+$N$2,IFERROR(INDEX(CLOZE_LIST!$A:$K,ROW()-1-$L$2-$M$2+1,3),""),IF(ROW()-1<=$L$2+$M$2+$N$2+$O$2,IFERROR(INDEX(PROFORMA!$A:$K,ROW()-1-$L$2-$M$2-$N$2+1,3),""),""))))) -> 0 | D11: =IF(ROW()-1<=0,"",IF(ROW()-1<=$L$2,IFERROR(INDEX(MCQ!$A:$K,ROW()-1+1,4),""),IF(ROW()-1<=$L$2+$M$2,IFERROR(INDEX(CLOZE_AB!$A:$K,ROW()-1-$L$2+1,4),""),IF(ROW()-1<=$L$2+$M$2+$N$2,IFERROR(INDEX(CLOZE_LIST!$A:$K,ROW()-1-$L$2-$M$2+1,4),""),IF(ROW()-1<=$L$2+$M$2+$N$2+$O$2,IFERROR(INDEX(PROFORMA!$A:$K,ROW()-1-$L$2-$M$2-$N$2+1,4),""),""))))) -> 0 | E11: =IF(ROW()-1<=0,"",IF(ROW()-1<=$L$2,IFERROR(INDEX(MCQ!$A:$K,ROW()-1+1,5),""),IF(ROW()-1<=$L$2+$M$2,IFERROR(INDEX(CLOZE_AB!$A:$K,ROW()-1-$L$2+1,5),""),IF(ROW()-1<=$L$2+$M$2+$N$2,IFERROR(INDEX(CLOZE_LIST!$A:$K,ROW()-1-$L$2-$M$2+1,5),""),IF(ROW()-1<=$L$2+$M$2+$N$2+$O$2,IFERROR(INDEX(PROFORMA!$A:$K,ROW()-1-$L$2-$M$2-$N$2+1,5),""),""))))) -> mcq_radio | F11: =IF(ROW()-1<=0,"",IF(ROW()-1<=$L$2,IFERROR(INDEX(MCQ!$A:$K,ROW()-1+1,6),""),IF(ROW()-1<=$L$2+$M$2,IFERROR(INDEX(CLOZE_AB!$A:$K,ROW()-1-$L$2+1,6),""),IF(ROW()-1<=$L$2+$M$2+$N$2,IFERROR(INDEX(CLOZE_LIST!$A:$K,ROW()-1-$L$2-$M$2+1,6),""),IF(ROW()-1<=$L$2+$M$2+$N$2+$O$2,IFERROR(INDEX(PROFORMA!$A:$K,ROW()-1-$L$2-$M$2-$N$2+1,6),""),""))))) -> 0 | G11: =IF(ROW()-1<=0,"",IF(ROW()-1<=$L$2,IFERROR(INDEX(MCQ!$A:$K,ROW()-1+1,7),""),IF(ROW()-1<=$L$2+$M$2,IFERROR(INDEX(CLOZE_AB!$A:$K,ROW()-1-$L$2+1,7),""),IF(ROW()-1<=$L$2+$M$2+$N$2,IFERROR(INDEX(CLOZE_LIST!$A:$K,ROW()-1-$L$2-$M$2+1,7),""),IF(ROW()-1<=$L$2+$M$2+$N$2+$O$2,IFERROR(INDEX(PROFORMA!$A:$K,ROW()-1-$L$2-$M$2-$N$2+1,7),""),""))))) -> 0 | H11: =IF(ROW()-1<=0,"",IF(ROW()-1<=$L$2,IFERROR(INDEX(MCQ!$A:$K,ROW()-1+1,8),""),IF(ROW()-1<=$L$2+$M$2,IFERROR(INDEX(CLOZE_AB!$A:$K,ROW()-1-$L$2+1,8),""),IF(ROW()-1<=$L$2+$M$2+$N$2,IFERROR(INDEX(CLOZE_LIST!$A:$K,ROW()-1-$L$2-$M$2+1,8),""),IF(ROW()-1<=$L$2+$M$2+$N$2+$O$2,IFERROR(INDEX(PROFORMA!$A:$K,ROW()-1-$L$2-$M$2-$N$2+1,8),""),""))))) -> 0 | I11: =IF(ROW()-1<=0,"",IF(ROW()-1<=$L$2,IFERROR(INDEX(MCQ!$A:$K,ROW()-1+1,9),""),IF(ROW()-1<=$L$2+$M$2,IFERROR(INDEX(CLOZE_AB!$A:$K,ROW()-1-$L$2+1,9),""),IF(ROW()-1<=$L$2+$M$2+$N$2,IFERROR(INDEX(CLOZE_LIST!$A:$K,ROW()-1-$L$2-$M$2+1,9),""),IF(ROW()-1<=$L$2+$M$2+$N$2+$O$2,IFERROR(INDEX(PROFORMA!$A:$K,ROW()-1-$L$2-$M$2-$N$2+1,9),""),""))))) -> 0 | J11: =IF(ROW()-1<=0,"",IF(ROW()-1<=$L$2,IFERROR(INDEX(MCQ!$A:$K,ROW()-1+1,10),""),IF(ROW()-1<=$L$2+$M$2,IFERROR(INDEX(CLOZE_AB!$A:$K,ROW()-1-$L$2+1,10),""),IF(ROW()-1<=$L$2+$M$2+$N$2,IFERROR(INDEX(CLOZE_LIST!$A:$K,ROW()-1-$L$2-$M$2+1,10),""),IF(ROW()-1<=$L$2+$M$2+$N$2+$O$2,IFERROR(INDEX(PROFORMA!$A:$K,ROW()-1-$L$2-$M$2-$N$2+1,10),""),""))))) -> 0 | K11: =IF(ROW()-1<=0,"",IF(ROW()-1<=$L$2,IFERROR(INDEX(MCQ!$A:$K,ROW()-1+1,11),""),IF(ROW()-1<=$L$2+$M$2,IFERROR(INDEX(CLOZE_AB!$A:$K,ROW()-1-$L$2+1,11),""),IF(ROW()-1<=$L$2+$M$2+$N$2,IFERROR(INDEX(CLOZE_LIST!$A:$K,ROW()-1-$L$2-$M$2+1,11),""),IF(ROW()-1<=$L$2+$M$2+$N$2+$O$2,IFERROR(INDEX(PROFORMA!$A:$K,ROW()-1-$L$2-$M$2-$N$2+1,11),""),""))))) -> 0
A12: =IF(ROW()-1<=0,"",IF(ROW()-1<=$L$2,IFERROR(INDEX(MCQ!$A:$K,ROW()-1+1,1),""),IF(ROW()-1<=$L$2+$M$2,IFERROR(INDEX(CLOZE_AB!$A:$K,ROW()-1-$L$2+1,1),""),IF(ROW()-1<=$L$2+$M$2+$N$2,IFERROR(INDEX(CLOZE_LIST!$A:$K,ROW()-1-$L$2-$M$2+1,1),""),IF(ROW()-1<=$L$2+$M$2+$N$2+$O$2,IFERROR(INDEX(PROFORMA!$A:$K,ROW()-1-$L$2-$M$2-$N$2+1,1),""),""))))) | B12: =IF(ROW()-1<=0,"",IF(ROW()-1<=$L$2,IFERROR(INDEX(MCQ!$A:$K,ROW()-1+1,2),""),IF(ROW()-1<=$L$2+$M$2,IFERROR(INDEX(CLOZE_AB!$A:$K,ROW()-1-$L$2+1,2),""),IF(ROW()-1<=$L$2+$M$2+$N$2,IFERROR(INDEX(CLOZE_LIST!$A:$K,ROW()-1-$L$2-$M$2+1,2),""),IF(ROW()-1<=$L$2+$M$2+$N$2+$O$2,IFERROR(INDEX(PROFORMA!$A:$K,ROW()-1-$L$2-$M$2-$N$2+1,2),""),""))))) -> 0 | C12: =IF(ROW()-1<=0,"",IF(ROW()-1<=$L$2,IFERROR(INDEX(MCQ!$A:$K,ROW()-1+1,3),""),IF(ROW()-1<=$L$2+$M$2,IFERROR(INDEX(CLOZE_AB!$A:$K,ROW()-1-$L$2+1,3),""),IF(ROW()-1<=$L$2+$M$2+$N$2,IFERROR(INDEX(CLOZE_LIST!$A:$K,ROW()-1-$L$2-$M$2+1,3),""),IF(ROW()-1<=$L$2+$M$2+$N$2+$O$2,IFERROR(INDEX(PROFORMA!$A:$K,ROW()-1-$L$2-$M$2-$N$2+1,3),""),""))))) -> 0 | D12: =IF(ROW()-1<=0,"",IF(ROW()-1<=$L$2,IFERROR(INDEX(MCQ!$A:$K,ROW()-1+1,4),""),IF(ROW()-1<=$L$2+$M$2,IFERROR(INDEX(CLOZE_AB!$A:$K,ROW()-1-$L$2+1,4),""),IF(ROW()-1<=$L$2+$M$2+$N$2,IFERROR(INDEX(CLOZE_LIST!$A:$K,ROW()-1-$L$2-$M$2+1,4),""),IF(ROW()-1<=$L$2+$M$2+$N$2+$O$2,IFERROR(INDEX(PROFORMA!$A:$K,ROW()-1-$L$2-$M$2-$N$2+1,4),""),""))))) -> 0 | E12: =IF(ROW()-1<=0,"",IF(ROW()-1<=$L$2,IFERROR(INDEX(MCQ!$A:$K,ROW()-1+1,5),""),IF(ROW()-1<=$L$2+$M$2,IFERROR(INDEX(CLOZE_AB!$A:$K,ROW()-1-$L$2+1,5),""),IF(ROW()-1<=$L$2+$M$2+$N$2,IFERROR(INDEX(CLOZE_LIST!$A:$K,ROW()-1-$L$2-$M$2+1,5),""),IF(ROW()-1<=$L$2+$M$2+$N$2+$O$2,IFERROR(INDEX(PROFORMA!$A:$K,ROW()-1-$L$2-$M$2-$N$2+1,5),""),""))))) -> mcq_radio | F12: =IF(ROW()-1<=0,"",IF(ROW()-1<=$L$2,IFERROR(INDEX(MCQ!$A:$K,ROW()-1+1,6),""),IF(ROW()-1<=$L$2+$M$2,IFERROR(INDEX(CLOZE_AB!$A:$K,ROW()-1-$L$2+1,6),""),IF(ROW()-1<=$L$2+$M$2+$N$2,IFERROR(INDEX(CLOZE_LIST!$A:$K,ROW()-1-$L$2-$M$2+1,6),""),IF(ROW()-1<=$L$2+$M$2+$N$2+$O$2,IFERROR(INDEX(PROFORMA!$A:$K,ROW()-1-$L$2-$M$2-$N$2+1,6),""),""))))) -> 0 | G12: =IF(ROW()-1<=0,"",IF(ROW()-1<=$L$2,IFERROR(INDEX(MCQ!$A:$K,ROW()-1+1,7),""),IF(ROW()-1<=$L$2+$M$2,IFERROR(INDEX(CLOZE_AB!$A:$K,ROW()-1-$L$2+1,7),""),IF(ROW()-1<=$L$2+$M$2+$N$2,IFERROR(INDEX(CLOZE_LIST!$A:$K,ROW()-1-$L$2-$M$2+1,7),""),IF(ROW()-1<=$L$2+$M$2+$N$2+$O$2,IFERROR(INDEX(PROFORMA!$A:$K,ROW()-1-$L$2-$M$2-$N$2+1,7),""),""))))) -> 0 | H12: =IF(ROW()-1<=0,"",IF(ROW()-1<=$L$2,IFERROR(INDEX(MCQ!$A:$K,ROW()-1+1,8),""),IF(ROW()-1<=$L$2+$M$2,IFERROR(INDEX(CLOZE_AB!$A:$K,ROW()-1-$L$2+1,8),""),IF(ROW()-1<=$L$2+$M$2+$N$2,IFERROR(INDEX(CLOZE_LIST!$A:$K,ROW()-1-$L$2-$M$2+1,8),""),IF(ROW()-1<=$L$2+$M$2+$N$2+$O$2,IFERROR(INDEX(PROFORMA!$A:$K,ROW()-1-$L$2-$M$2-$N$2+1,8),""),""))))) -> 0 | I12: =IF(ROW()-1<=0,"",IF(ROW()-1<=$L$2,IFERROR(INDEX(MCQ!$A:$K,ROW()-1+1,9),""),IF(ROW()-1<=$L$2+$M$2,IFERROR(INDEX(CLOZE_AB!$A:$K,ROW()-1-$L$2+1,9),""),IF(ROW()-1<=$L$2+$M$2+$N$2,IFERROR(INDEX(CLOZE_LIST!$A:$K,ROW()-1-$L$2-$M$2+1,9),""),IF(ROW()-1<=$L$2+$M$2+$N$2+$O$2,IFERROR(INDEX(PROFORMA!$A:$K,ROW()-1-$L$2-$M$2-$N$2+1,9),""),""))))) -> 0 | J12: =IF(ROW()-1<=0,"",IF(ROW()-1<=$L$2,IFERROR(INDEX(MCQ!$A:$K,ROW()-1+1,10),""),IF(ROW()-1<=$L$2+$M$2,IFERROR(INDEX(CLOZE_AB!$A:$K,ROW()-1-$L$2+1,10),""),IF(ROW()-1<=$L$2+$M$2+$N$2,IFERROR(INDEX(CLOZE_LIST!$A:$K,ROW()-1-$L$2-$M$2+1,10),""),IF(ROW()-1<=$L$2+$M$2+$N$2+$O$2,IFERROR(INDEX(PROFORMA!$A:$K,ROW()-1-$L$2-$M$2-$N$2+1,10),""),""))))) -> 0 | K12: =IF(ROW()-1<=0,"",IF(ROW()-1<=$L$2,IFERROR(INDEX(MCQ!$A:$K,ROW()-1+1,11),""),IF(ROW()-1<=$L$2+$M$2,IFERROR(INDEX(CLOZE_AB!$A:$K,ROW()-1-$L$2+1,11),""),IF(ROW()-1<=$L$2+$M$2+$N$2,IFERROR(INDEX(CLOZE_LIST!$A:$K,ROW()-1-$L$2-$M$2+1,11),""),IF(ROW()-1<=$L$2+$M$2+$N$2+$O$2,IFERROR(INDEX(PROFORMA!$A:$K,ROW()-1-$L$2-$M$2-$N$2+1,11),""),""))))) -> 0
